Workbook
Name \p: #REF!
Name \Q: #REF!
Name \t: #REF!
Name \v: #REF!
Name ____DAT1: #REF!
Name ____DAT10: #REF!
Name ____DAT11: #REF!
Name ____DAT12: #REF!
Name ____DAT13: #REF!
Name ____DAT14: #REF!
Name ____DAT2: #REF!
Name ____DAT3: #REF!
Name ____DAT4: #REF!
Name ____DAT5: #REF!
Name ____DAT6: #REF!
Name ____DAT7: #REF!
Name ____DAT8: #REF!
Name ____DAT9: #REF!
Name ____tab2: #REF!
Name ____tab6: #REF!
Name ___DAT1: #REF!
Name ___DAT10: #REF!
Name ___DAT11: #REF!
Name ___DAT12: #REF!
Name ___DAT13: #REF!
Name ___DAT14: #REF!
Name ___DAT2: #REF!
Name ___DAT3: #REF!
Name ___DAT4: #REF!
Name ___DAT5: #REF!
Name ___DAT6: #REF!
Name ___DAT7: #REF!
Name ___DAT8: #REF!
Name ___DAT9: #REF!
Name ___tab2: #REF!
Name ___tab6: #REF!
Name __DAT1: #REF!
Name __DAT10: #REF!
Name __DAT11: #REF!
Name __DAT12: #REF!
Name __DAT13: #REF!
Name __DAT14: #REF!
Name __DAT15: #REF!
Name __DAT16: #REF!
Name __DAT17: #REF!
Name __DAT18: #REF!
Name __DAT19: #REF!
Name __DAT2: #REF!
Name __DAT20: #REF!
Name __DAT21: #REF!
Name __DAT22: #REF!
Name __DAT23: #REF!
Name __DAT24: #REF!
Name __DAT3: #REF!
Name __DAT4: #REF!
Name __DAT5: #REF!
Name __DAT6: #REF!
Name __DAT7: #REF!
Name __DAT8: #REF!
Name __DAT9: #REF!

Sheet Executive Summary
B1: EXPORA MIS YTD AUG 2027
B4: Currency (Rs) | C4: Consolidated
C5: 46113 | D5: 46143 | E5: 46174 | F5: 46204 | G5: 46235 | H5: YTD 2627
B6: Revenue Booked | C6: =C25+C59+C78 -> #REF! | D6: =D25+D59+D78 -> #REF! | E6: =E25+E59+E78 -> #REF! | F6: =F25+F59+F78 -> #REF! | G6: =G25+G59+G78 -> #REF! | H6: =SUM(C6:G6) -> #REF!
B7: COGS | C7: =C26+C60+C79 -> #REF! | D7: =D26+D60+D79 -> #REF! | E7: =E26+E60+E79 -> #REF! | F7: =F26+F60+F79 -> #REF! | G7: =G26+G60+G79 -> #REF! | H7: =SUM(C7:G7) -> #REF!
B8: GM | C8: =C6-C7 -> #REF! | D8: =D6-D7 -> #REF! | E8: =E6-E7 -> #REF! | F8: =F6-F7 -> #REF! | G8: =G6-G7 -> #REF! | H8: =H6-H7 -> #REF!
B9: GM% | C9: =C8/C6 -> #REF! | D9: =D8/D6 -> #REF! | E9: =E8/E6 -> #REF! | F9: =F8/F6 -> #REF! | G9: =G8/G6 -> #REF! | H9: =H8/H6 -> #REF!
B10: Direct Expenses | C10: =C29+C63+C82 -> #REF! | D10: =D29+D63+D82 -> #REF! | E10: =E29+E63+E82 -> #REF! | F10: =F29+F63+F82 -> #REF! | G10: =G29+G63+G82 -> #REF! | H10: =SUM(C10:G10) -> #REF!
B11: CM | C11: =C30+C64+C83 -> #REF! | D11: =D30+D64+D83 -> #REF! | E11: =E30+E64+E83 -> #REF! | F11: =F30+F64+F83 -> #REF! | G11: =G30+G64+G83 -> #REF! | H11: =SUM(C11:G11) -> #REF!
B12: CM% | C12: =C11/C6 -> #REF! | D12: =D11/D6 -> #REF! | E12: =E11/E6 -> #REF! | F12: =F11/F6 -> #REF! | G12: =G11/G6 -> #REF! | H12: =H11/H6 -> #REF!
B13: Other Income | C13: =C32+C66+C85 -> #REF! | D13: =D32+D66+D85 -> #REF! | E13: =E32+E66+E85 -> #REF! | F13: =F32+F66+F85 -> #REF! | G13: =G32+G66+G85 -> #REF! | H13: =SUM(C13:G13) -> #REF!
B14: Fixed Expenses | C14: =C33+C67+C86 -> #REF! | D14: =D33+D67+D86 -> #REF! | E14: =E33+E67+E86 -> #REF! | F14: =F33+F67+F86 -> #REF! | G14: =G33+G67+G86 -> #REF! | H14: =SUM(C14:G14) -> #REF!
B15: EBITDA | C15: =C11+C13-C14 -> #REF! | D15: =D11+D13-D14 -> #REF! | E15: =E11+E13-E14 -> #REF! | F15: =F11+F13-F14 -> #REF! | G15: =G11+G13-G14 -> #REF! | H15: =SUM(C15:G15) -> #REF!
B16: EBITDA% | C16: =C15/C6 -> #REF! | D16: =D15/D6 -> #REF! | E16: =E15/E6 -> #REF! | F16: =F15/F6 -> #REF! | G16: =G15/G6 -> #REF! | H16: =H15/H6 -> #REF!
B17: Finance Cost | C17: =C36+C70+C89 -> #REF! | D17: =D36+D70+D89 -> #REF! | E17: =E36+E70+E89 -> #REF! | F17: =F36+F70+F89 -> #REF! | G17: =G36+G70+G89 -> #REF! | H17: =SUM(C17:G17) -> #REF!
B18: Depriciation | C18: =C37+C71+C90 -> #REF! | D18: =D37+D71+D90 -> #REF! | E18: =E37+E71+E90 -> #REF! | F18: =F37+F71+F90 -> #REF! | G18: =G37+G71+G90 -> #REF! | H18: =SUM(C18:G18) -> #REF!
B19: FX Gain/loss | C19: =C38+C72+C91 -> #REF! | D19: =D38+D72+D91 -> #REF! | E19: =E38+E72+E91 -> #REF! | F19: =F38+F72+F91 -> #REF! | G19: =G38+G72+G91 -> #REF! | H19: =SUM(C19:G19) -> #REF!
B20: Net Profit | C20: =C39+C73+C92 -> #REF! | D20: =D39+D73+D92 -> #REF! | E20: =E39+E73+E92 -> #REF! | F20: =F39+F73+F92 -> #REF! | G20: =G39+G73+G92 -> #REF! | H20: =SUM(C20:G20) -> #REF!
B21: Net Profit % | C21: =C20/C6 -> #REF! | D21: =D20/D6 -> #REF! | E21: =E20/E6 -> #REF! | F21: =F20/F6 -> #REF! | G21: =G20/G6 -> #REF! | H21: =H20/H6 -> #REF!
B23: Currency (Rs) | C23: Tradearch
C24: 46113 | D24: 46143 | E24: 46174 | F24: 46204 | G24: 46235 | H24: YTD 2627
B25: Revenue Booked | C25: =PL!#REF! -> #REF! | D25: =PL!#REF! -> #REF! | E25: =PL!#REF! -> #REF! | F25: =PL!#REF! -> #REF! | G25: =PL!#REF! -> #REF! | H25: =SUM(C25:G25) -> #REF!
B26: COGS | C26: =PL!#REF! -> #REF! | D26: =PL!#REF! -> #REF! | E26: =PL!#REF! -> #REF! | F26: =PL!#REF! -> #REF! | G26: =PL!#REF! -> #REF! | H26: =SUM(C26:G26) -> #REF!
B27: GM | C27: =C25-C26 -> #REF! | D27: =D25-D26 -> #REF! | E27: =E25-E26 -> #REF! | F27: =F25-F26 -> #REF! | G27: =G25-G26 -> #REF! | H27: =H25-H26 -> #REF!
B28: GM% | C28: =C27/C25 -> #REF! | D28: =D27/D25 -> #REF! | E28: =E27/E25 -> #REF! | F28: =F27/F25 -> #REF! | G28: =G27/G25 -> #REF! | H28: =H27/H25 -> #REF!
B29: Direct Expenses | C29: =PL!#REF!-PL!#REF! -> #REF! | D29: =PL!#REF!-PL!#REF! -> #REF! | E29: =PL!#REF!-PL!#REF! -> #REF! | F29: =PL!#REF!-PL!#REF! -> #REF! | G29: =PL!#REF!-PL!#REF! -> #REF! | H29: =SUM(C29:G29) -> #REF!
B30: CM | C30: =C27-C29 -> #REF! | D30: =D27-D29 -> #REF! | E30: =E27-E29 -> #REF! | F30: =F27-F29 -> #REF! | G30: =G27-G29 -> #REF! | H30: =SUM(C30:G30) -> #REF!
B31: CM% | C31: =C30/C25 -> #REF! | D31: =D30/D25 -> #REF! | E31: =E30/E25 -> #REF! | F31: =F30/F25 -> #REF! | G31: =G30/G25 -> #REF! | H31: =H30/H25 -> #REF!
B32: Other Income | C32: =PL!#REF! -> #REF! | D32: =PL!#REF! -> #REF! | E32: =PL!#REF! -> #REF! | F32: =PL!#REF! -> #REF! | G32: =PL!#REF! -> #REF! | H32: =SUM(C32:G32) -> #REF!
B33: Fixed Expenses | C33: =PL!#REF! -> #REF! | D33: =PL!#REF! -> #REF! | E33: =PL!#REF! -> #REF! | F33: =PL!#REF! -> #REF! | G33: =PL!#REF! -> #REF! | H33: =SUM(C33:G33) -> #REF!
B34: EBITDA | C34: =C30+C32-C33 -> #REF! | D34: =D30+D32-D33 -> #REF! | E34: =E30+E32-E33 -> #REF! | F34: =F30+F32-F33 -> #REF! | G34: =G30+G32-G33 -> #REF! | H34: =SUM(C34:G34) -> #REF!
B35: EBITDA% | C35: =C34/C25 -> #REF! | D35: =D34/D25 -> #REF! | E35: =E34/E25 -> #REF! | F35: =F34/F25 -> #REF! | G35: =G34/G25 -> #REF! | H35: =H34/H25 -> #REF!
B36: Finance Cost | C36: =PL!#REF! -> #REF! | D36: =PL!#REF! -> #REF! | E36: =PL!#REF! -> #REF! | F36: =PL!#REF! -> #REF! | G36: =PL!#REF! -> #REF! | H36: =SUM(C36:G36) -> #REF!
B37: Depriciation | C37: =PL!#REF! -> #REF! | D37: =PL!#REF! -> #REF! | E37: =PL!#REF! -> #REF! | F37: =PL!#REF! -> #REF! | G37: =PL!#REF! -> #REF! | H37: =SUM(C37:G37) -> #REF!
B38: FX Gain/loss | C38: =PL!#REF! -> #REF! | D38: =PL!#REF! -> #REF! | E38: =PL!#REF! -> #REF! | F38: =PL!#REF! -> #REF! | G38: =PL!#REF! -> #REF! | H38: =SUM(C38:G38) -> #REF!
B39: Net Profit | C39: =C34-C36-C37-C38 -> #REF! | D39: =D34-D36-D37-D38 -> #REF! | E39: =E34-E36-E37-E38 -> #REF! | F39: =F34-F36-F37-F38 -> #REF! | G39: =G34-G36-G37-G38 -> #REF! | H39: =SUM(C39:G39) -> #REF!
B40: Net Profit % | C40: =C39/C25 -> #REF! | D40: =D39/D25 -> #REF! | E40: =E39/E25 -> #REF! | F40: =F39/F25 -> #REF! | G40: =G39/G25 -> #REF! | H40: =H39/H25 -> #REF!
B57: Currency (Rs) | C57: Arha General Trading Co (AGT)
C58: 46113 | D58: 46143 | E58: 46174 | F58: 46204 | G58: 46235 | H58: YTD 2627
B59: Revenue Booked | C59: =PL!C6 -> 0 | D59: =PL!D6 -> 0 | E59: =PL!E6 -> 0 | F59: =PL!F6 -> 0 | G59: =PL!G6 -> 0 | H59: =SUM(C59:G59) -> 0
...

Sheet PL
B1: Tradearch Market Platforms Private Limited
B2: Profit and Loss for the period April 21 to October 2024 | C2: =#REF! -> #REF!
B3: Figures in Rs
C4: AGT
B5: Currency (Rs) | C5: Apr-25 | D5: May-25 | E5: June-25 | F5: July-25 | G5: Aug-25 | H5: YTD FY26
B6: Revenue Booked | C6: =SUM(C7:C8) -> 0 | D6: =SUM(D7:D8) -> 0 | E6: =SUM(E7:E8) -> 0 | F6: =SUM(F7:F8) -> 0 | G6: =SUM(G7:G8) -> 0 | H6: =SUM(C6:G6) -> 0
B7: Sales | C7: =-SUMIFS('AGT TB Apr -25'!H:H,'AGT TB Apr -25'!S:S,B7) -> 0 | D7: =-SUMIFS('AGT TB Apr -25'!I:I,'AGT TB Apr -25'!S:S,B7) -> 0 | E7: =-SUMIFS('AGT TB Apr -25'!J:J,'AGT TB Apr -25'!S:S,B7) -> 0 | F7: =-SUMIFS('AGT TB Apr -25'!K:K,'AGT TB Apr -25'!S:S,B7) -> 0 | G7: =-SUMIFS('AGT TB Apr -25'!L:L,'AGT TB Apr -25'!S:S,B7) -> 0 | H7: =SUM(C7:G7) -> 0
B8: Cash Discount - Income | C8: =-SUMIFS('AGT TB Apr -25'!H:H,'AGT TB Apr -25'!S:S,B8) -> 0 | D8: =-SUMIFS('AGT TB Apr -25'!I:I,'AGT TB Apr -25'!S:S,B8) -> 0 | E8: =-SUMIFS('AGT TB Apr -25'!J:J,'AGT TB Apr -25'!S:S,B8) -> 0 | F8: =-SUMIFS('AGT TB Apr -25'!K:K,'AGT TB Apr -25'!S:S,B8) -> 0 | G8: =-SUMIFS('AGT TB Apr -25'!L:L,'AGT TB Apr -25'!S:S,B8) -> 0 | H8: =SUM(C8:G8) -> 0
B9: Inventorisation | C9: =SUMIFS('AGT TB Apr -25'!H:H,'AGT TB Apr -25'!S:S,B9) -> 0 | D9: =SUMIFS('AGT TB Apr -25'!I:I,'AGT TB Apr -25'!S:S,B9) -> 0 | E9: =SUMIFS('AGT TB Apr -25'!J:J,'AGT TB Apr -25'!S:S,B9) -> 0 | F9: =SUMIFS('AGT TB Apr -25'!K:K,'AGT TB Apr -25'!S:S,B9) -> 0 | G9: =SUMIFS('AGT TB Apr -25'!L:L,'AGT TB Apr -25'!S:S,B9) -> 0 | H9: =SUM(C9:G9) -> 0
B10: COGS | C10: =SUMIFS('AGT TB Apr -25'!H:H,'AGT TB Apr -25'!S:S,B10) -> 0 | D10: =SUMIFS('AGT TB Apr -25'!I:I,'AGT TB Apr -25'!S:S,B10) -> 0 | E10: =SUMIFS('AGT TB Apr -25'!J:J,'AGT TB Apr -25'!S:S,B10) -> 0 | F10: =SUMIFS('AGT TB Apr -25'!K:K,'AGT TB Apr -25'!S:S,B10) -> 0 | G10: =SUMIFS('AGT TB Apr -25'!L:L,'AGT TB Apr -25'!S:S,B10) -> 0 | H10: =SUM(C10:G10) -> 0
A11: =#REF!+#REF!-#REF! -> #REF! | B11: Opening Stock | C11: ='AGT TB Apr -25'!#REF! -> #REF! | D11: ='AGT TB Apr -25'!#REF! -> #REF! | E11: ='AGT TB Apr -25'!#REF! -> #REF! | F11: ='AGT TB Apr -25'!#REF! -> #REF! | G11: ='AGT TB Apr -25'!#REF! -> #REF! | H11: =SUM(C11:G11) -> #REF!
B12: Purchase | C12: =SUMIFS('AGT TB Apr -25'!H:H,'AGT TB Apr -25'!S:S,B12) -> 0 | D12: =SUMIFS('AGT TB Apr -25'!I:I,'AGT TB Apr -25'!S:S,B12) -> 0 | E12: =SUMIFS('AGT TB Apr -25'!J:J,'AGT TB Apr -25'!S:S,B12) -> 0 | F12: =SUMIFS('AGT TB Apr -25'!K:K,'AGT TB Apr -25'!S:S,B12) -> 0 | G12: =SUMIFS('AGT TB Apr -25'!L:L,'AGT TB Apr -25'!S:S,B12) -> 0 | H12: =SUM(C12:G12) -> 0
A13: =#REF! -> #REF! | H13: =SUM(C13:G13) -> 0
B14: Closing Stock | C14: =SUMIFS('AGT TB Apr -25'!H:H,'AGT TB Apr -25'!S:S,B14) -> 0 | D14: =SUMIFS('AGT TB Apr -25'!I:I,'AGT TB Apr -25'!S:S,B14) -> 0 | E14: =SUMIFS('AGT TB Apr -25'!J:J,'AGT TB Apr -25'!S:S,B14) -> 0 | F14: =SUMIFS('AGT TB Apr -25'!K:K,'AGT TB Apr -25'!S:S,B14) -> 0 | G14: =SUMIFS('AGT TB Apr -25'!L:L,'AGT TB Apr -25'!S:S,B14) -> 0 | H14: =SUM(C14:G14) -> 0
B15: Direct Income | C15: =SUM(C16:C18) -> 0 | D15: =SUM(D16:D18) -> 0 | E15: =SUM(E16:E18) -> 0 | F15: =SUM(F16:F18) -> 0 | G15: =SUM(G16:G18) -> 0 | H15: =SUM(C15:G15) -> 0
B16: Duty Drawback | C16: =-SUMIFS('AGT TB Apr -25'!H:H,'AGT TB Apr -25'!S:S,B16) -> 0 | D16: =-SUMIFS('AGT TB Apr -25'!I:I,'AGT TB Apr -25'!S:S,B16) -> 0 | E16: =-SUMIFS('AGT TB Apr -25'!J:J,'AGT TB Apr -25'!S:S,B16) -> 0 | F16: =-SUMIFS('AGT TB Apr -25'!K:K,'AGT TB Apr -25'!S:S,B16) -> 0 | G16: =-SUMIFS('AGT TB Apr -25'!L:L,'AGT TB Apr -25'!S:S,B16) -> 0 | H16: =SUM(C16:G16) -> 0
B17: Making Charges | C17: =-SUMIFS('AGT TB Apr -25'!H:H,'AGT TB Apr -25'!S:S,B17) -> 0 | D17: =-SUMIFS('AGT TB Apr -25'!I:I,'AGT TB Apr -25'!S:S,B17) -> 0 | E17: =-SUMIFS('AGT TB Apr -25'!J:J,'AGT TB Apr -25'!S:S,B17) -> 0 | F17: =-SUMIFS('AGT TB Apr -25'!K:K,'AGT TB Apr -25'!S:S,B17) -> 0 | G17: =-SUMIFS('AGT TB Apr -25'!L:L,'AGT TB Apr -25'!S:S,B17) -> 0 | H17: =SUM(C17:G17) -> 0
A18: =#REF!+#REF!-#REF! -> #REF! | B18: Rodtep Income | C18: =-SUMIFS('AGT TB Apr -25'!H:H,'AGT TB Apr -25'!S:S,B18) -> 0 | D18: =-SUMIFS('AGT TB Apr -25'!I:I,'AGT TB Apr -25'!S:S,B18) -> 0 | E18: =-SUMIFS('AGT TB Apr -25'!J:J,'AGT TB Apr -25'!S:S,B18) -> 0 | F18: =-SUMIFS('AGT TB Apr -25'!K:K,'AGT TB Apr -25'!S:S,B18) -> 0 | G18: =-SUMIFS('AGT TB Apr -25'!L:L,'AGT TB Apr -25'!S:S,B18) -> 0 | H18: =SUM(C18:G18) -> 0
B19: Direct Expenses | C19: =SUM(C20:C40) -> 0 | D19: =SUM(D20:D40) -> 0 | E19: =SUM(E20:E40) -> 0 | F19: =SUM(F20:F40) -> 0 | G19: =SUM(G20:G40) -> 0 | H19: =SUM(C19:G19) -> 0
B20: Labour charges on Gold & Diamond | C20: =-SUMIFS('AGT TB Apr -25'!H:H,'AGT TB Apr -25'!S:S,B20) -> 0 | D20: =-SUMIFS('AGT TB Apr -25'!I:I,'AGT TB Apr -25'!S:S,B20) -> 0 | E20: =-SUMIFS('AGT TB Apr -25'!J:J,'AGT TB Apr -25'!S:S,B20) -> 0 | F20: =-SUMIFS('AGT TB Apr -25'!K:K,'AGT TB Apr -25'!S:S,B20) -> 0 | G20: =-SUMIFS('AGT TB Apr -25'!L:L,'AGT TB Apr -25'!S:S,B20) -> 0 | H20: =SUM(C20:G20) -> 0
B21: Provision for Direct Expense | H21: =SUM(C21:G21) -> 0
B22: Freight & forwarding Charges | C22: =SUMIFS('AGT TB Apr -25'!H:H,'AGT TB Apr -25'!S:S,B22) -> 0 | D22: =SUMIFS('AGT TB Apr -25'!I:I,'AGT TB Apr -25'!S:S,B22) -> 0 | E22: =SUMIFS('AGT TB Apr -25'!J:J,'AGT TB Apr -25'!S:S,B22) -> 0 | F22: =SUMIFS('AGT TB Apr -25'!K:K,'AGT TB Apr -25'!S:S,B22) -> 0 | G22: =SUMIFS('AGT TB Apr -25'!L:L,'AGT TB Apr -25'!S:S,B22) -> 0 | H22: =SUM(C22:G22) -> 0
B23: Labour Charges | C23: =SUMIFS('AGT TB Apr -25'!H:H,'AGT TB Apr -25'!S:S,B23) -> 0 | D23: =SUMIFS('AGT TB Apr -25'!I:I,'AGT TB Apr -25'!S:S,B23) -> 0 | E23: =SUMIFS('AGT TB Apr -25'!J:J,'AGT TB Apr -25'!S:S,B23) -> 0 | F23: =SUMIFS('AGT TB Apr -25'!K:K,'AGT TB Apr -25'!S:S,B23) -> 0 | G23: =SUMIFS('AGT TB Apr -25'!L:L,'AGT TB Apr -25'!S:S,B23) -> 0 | H23: =SUM(C23:G23) -> 0
B24: Prior Period Direct Expense | C24: =SUMIFS('AGT TB Apr -25'!H:H,'AGT TB Apr -25'!S:S,B24) -> 0 | D24: =SUMIFS('AGT TB Apr -25'!I:I,'AGT TB Apr -25'!S:S,B24) -> 0 | E24: =SUMIFS('AGT TB Apr -25'!J:J,'AGT TB Apr -25'!S:S,B24) -> 0 | F24: =SUMIFS('AGT TB Apr -25'!K:K,'AGT TB Apr -25'!S:S,B24) -> 0 | G24: =SUMIFS('AGT TB Apr -25'!L:L,'AGT TB Apr -25'!S:S,B24) -> 0 | H24: =SUM(C24:G24) -> 0
B25: Custom Duty | C25: =SUMIFS('AGT TB Apr -25'!H:H,'AGT TB Apr -25'!S:S,B25) -> 0 | D25: =SUMIFS('AGT TB Apr -25'!I:I,'AGT TB Apr -25'!S:S,B25) -> 0 | E25: =SUMIFS('AGT TB Apr -25'!J:J,'AGT TB Apr -25'!S:S,B25) -> 0 | F25: =SUMIFS('AGT TB Apr -25'!K:K,'AGT TB Apr -25'!S:S,B25) -> 0 | G25: =SUMIFS('AGT TB Apr -25'!L:L,'AGT TB Apr -25'!S:S,B25) -> 0 | H25: =SUM(C25:G25) -> 0
B26: Testing and Inspection Charge | C26: =SUMIFS('AGT TB Apr -25'!H:H,'AGT TB Apr -25'!S:S,B26) -> 0 | D26: =SUMIFS('AGT TB Apr -25'!I:I,'AGT TB Apr -25'!S:S,B26) -> 0 | E26: =SUMIFS('AGT TB Apr -25'!J:J,'AGT TB Apr -25'!S:S,B26) -> 0 | F26: =SUMIFS('AGT TB Apr -25'!K:K,'AGT TB Apr -25'!S:S,B26) -> 0 | G26: =SUMIFS('AGT TB Apr -25'!L:L,'AGT TB Apr -25'!S:S,B26) -> 0 | H26: =SUM(C26:G26) -> 0
B27: Transportation Charges | C27: =SUMIFS('AGT TB Apr -25'!H:H,'AGT TB Apr -25'!S:S,B27) -> 0 | D27: =SUMIFS('AGT TB Apr -25'!I:I,'AGT TB Apr -25'!S:S,B27) -> 0 | E27: =SUMIFS('AGT TB Apr -25'!J:J,'AGT TB Apr -25'!S:S,B27) -> 0 | F27: =SUMIFS('AGT TB Apr -25'!K:K,'AGT TB Apr -25'!S:S,B27) -> 0 | G27: =SUMIFS('AGT TB Apr -25'!L:L,'AGT TB Apr -25'!S:S,B27) -> 0 | H27: =SUM(C27:G27) -> 0
B28: Commission & Brokerage Charges | C28: =SUMIFS('AGT TB Apr -25'!H:H,'AGT TB Apr -25'!S:S,B28) -> 0 | D28: =SUMIFS('AGT TB Apr -25'!I:I,'AGT TB Apr -25'!S:S,B28) -> 0 | E28: =SUMIFS('AGT TB Apr -25'!J:J,'AGT TB Apr -25'!S:S,B28) -> 0 | F28: =SUMIFS('AGT TB Apr -25'!K:K,'AGT TB Apr -25'!S:S,B28) -> 0 | G28: =SUMIFS('AGT TB Apr -25'!L:L,'AGT TB Apr -25'!S:S,B28) -> 0 | H28: =SUM(C28:G28) -> 0
B29: Spice testing expenses | C29: =SUMIFS('AGT TB Apr -25'!H:H,'AGT TB Apr -25'!S:S,B29) -> 0 | D29: =SUMIFS('AGT TB Apr -25'!I:I,'AGT TB Apr -25'!S:S,B29) -> 0 | E29: =SUMIFS('AGT TB Apr -25'!J:J,'AGT TB Apr -25'!S:S,B29) -> 0 | F29: =SUMIFS('AGT TB Apr -25'!K:K,'AGT TB Apr -25'!S:S,B29) -> 0 | G29: =SUMIFS('AGT TB Apr -25'!L:L,'AGT TB Apr -25'!S:S,B29) -> 0 | H29: =SUM(C29:G29) -> 0
B30: Export Insurance Policy | C30: =SUMIFS('AGT TB Apr -25'!H:H,'AGT TB Apr -25'!S:S,B30) -> 0 | D30: =SUMIFS('AGT TB Apr -25'!I:I,'AGT TB Apr -25'!S:S,B30) -> 0 | E30: =SUMIFS('AGT TB Apr -25'!J:J,'AGT TB Apr -25'!S:S,B30) -> 0 | F30: =SUMIFS('AGT TB Apr -25'!K:K,'AGT TB Apr -25'!S:S,B30) -> 0 | G30: =SUMIFS('AGT TB Apr -25'!L:L,'AGT TB Apr -25'!S:S,B30) -> 0 | H30: =SUM(C30:G30) -> 0
B31: Bank charges against Import/MTT Transactio | C31: =SUMIFS('AGT TB Apr -25'!H:H,'AGT TB Apr -25'!S:S,B31) -> 0 | D31: =SUMIFS('AGT TB Apr -25'!I:I,'AGT TB Apr -25'!S:S,B31) -> 0 | E31: =SUMIFS('AGT TB Apr -25'!J:J,'AGT TB Apr -25'!S:S,B31) -> 0 | F31: =SUMIFS('AGT TB Apr -25'!K:K,'AGT TB Apr -25'!S:S,B31) -> 0 | G31: =SUMIFS('AGT TB Apr -25'!L:L,'AGT TB Apr -25'!S:S,B31) -> 0 | H31: =SUM(C31:G31) -> 0
B32: Cleaning & Packing | C32: =SUMIFS('AGT TB Apr -25'!H:H,'AGT TB Apr -25'!S:S,B32) -> 0 | D32: =SUMIFS('AGT TB Apr -25'!I:I,'AGT TB Apr -25'!S:S,B32) -> 0 | E32: =SUMIFS('AGT TB Apr -25'!J:J,'AGT TB Apr -25'!S:S,B32) -> 0 | F32: =SUMIFS('AGT TB Apr -25'!K:K,'AGT TB Apr -25'!S:S,B32) -> 0 | G32: =SUMIFS('AGT TB Apr -25'!L:L,'AGT TB Apr -25'!S:S,B32) -> 0 | H32: =SUM(C32:G32) -> 0
B33: QC Charges | C33: =SUMIFS('AGT TB Apr -25'!H:H,'AGT TB Apr -25'!S:S,B33) -> 0 | D33: =SUMIFS('AGT TB Apr -25'!I:I,'AGT TB Apr -25'!S:S,B33) -> 0 | E33: =SUMIFS('AGT TB Apr -25'!J:J,'AGT TB Apr -25'!S:S,B33) -> 0 | F33: =SUMIFS('AGT TB Apr -25'!K:K,'AGT TB Apr -25'!S:S,B33) -> 0 | G33: =SUMIFS('AGT TB Apr -25'!L:L,'AGT TB Apr -25'!S:S,B33) -> 0 | H33: =SUM(C33:G33) -> 0
... B40: Excess Weight Charges | C40: =SUMIFS('AGT TB Apr -25'!H:H,'AGT TB Apr -25'!S:S,B40) -> 0 | D40: =SUMIFS('AGT TB Apr -25'!I:I,'AGT TB Apr -25'!S:S,B40) -> 0 | E40: =SUMIFS('AGT TB Apr -25'!J:J,'AGT TB Apr -25'!S:S,B40) -> 0 | F40: =SUMIFS('AGT TB Apr -25'!K:K,'AGT TB Apr -25'!S:S,B40) -> 0 | G40: =SUMIFS('AGT TB Apr -25'!L:L,'AGT TB Apr -25'!S:S,B40) -> 0 | H40: =SUM(C40:G40) -> 0
B41: Gross Profit | C41: =C6-C10-C19+C15+C9 -> 0 | D41: =D6-D10-D19+D15+D9 -> 0 | E41: =E6-E10-E19+E15+E9 -> 0 | F41: =F6-F10-F19+F15+F9 -> 0 | G41: =G6-G10-G19+G15+G9 -> 0 | H41: =SUM(C41:G41) -> 0
B42: GP % | C42: =C41/C6% -> #DIV/0! | D42: =D41/D6% -> #DIV/0! | E42: =E41/E6% -> #DIV/0! | F42: =F41/F6% -> #DIV/0! | G42: =G41/G6% -> #DIV/0! | H42: =SUM(C42:G42) -> #DIV/0!
B43: Incorrect Provision Adjustment | H43: =SUM(C43:G43) -> 0
B44: Updated Gross Profit | C44: =C41+C43 -> 0 | D44: =D41+D43 -> 0 | E44: =E41+E43 -> 0 | F44: =F41+F43 -> 0 | G44: =G41+G43 -> 0 | H44: =SUM(C44:G44) -> 0
B45: Revised GP % | C45: =C44/C6% -> #DIV/0! | D45: =D44/D6% -> #DIV/0! | E45: =E44/E6% -> #DIV/0! | F45: =F44/F6% -> #DIV/0! | G45: =G44/G6% -> #DIV/0! | H45: =SUM(C45:G45) -> #DIV/0!
B46: Indirect Income | C46: =SUM(C47:C49) -> 0 | D46: =SUM(D47:D49) -> 0 | E46: =SUM(E47:E49) -> 0 | F46: =SUM(F47:F49) -> 0 | G46: =SUM(G47:G49) -> 0 | H46: =SUM(C46:G46) -> 0
...

Sheet PL1_AGT
B1: Arha Platforms General Trading LLC | F1: -22.83 | H1: ='AGT TB Apr -25'!N1 -> 26 | L1: =SUBTOTAL(9,L5:L568) -> 0 | W1: =SUBTOTAL(9,W5:W568) -> 0 | AC1: =SUBTOTAL(9,AC5:AC568) -> 0
B2: Revenue and Margin by Invoice
J3: Purchase | L3: Purchase | O3: Direct Expense | U3: Sales | W3: Sales | AC3: Margin | AD3: Margin
B4: Month | C4: Invoice Number | D4: Month | E4: Segment | F4: Product | G4: Vendor Name | H4: Customer Name | I4: Qty (Measure) | J4: Qty | K4: Rate | L4: Amount (P) | M4: Discount on Purchase | N4: Net Purchase cost | O4: Direct Expense P.U | P4: Direct Expenses Cost (F) | Q4: Total Cost | R4: Customer Country | S4: Partner Name | T4: Direct Expenses | U4: Qty | V4: Rate | W4: Amount | X4: Discount on Sales | Y4: Net Sales | Z4: Adjustment | AA4: Total After Adjustment (S) | AB4: Foreign Exchange Gain/ (Loss) | AC4: Gross Margin 1 | AD4: Gross Margin 2 | AE4: Gross Margin 1 (%) | AF4: Gross Margin 2 (%) | AG4: Remarks
B5: =EOMONTH(A5,0) -> 31 | J5: =U5 -> 0 | K5: =L5/J5 -> #DIV/0! | N5: =L5-M5 -> 0 | O5: =P5/J5 -> #DIV/0! | Q5: =N5+P5 -> 0 | V5: =W5/U5 -> #DIV/0! | Y5: =W5-X5 -> 0 | AA5: =Y5-Z5 -> 0 | AC5: =Y5-N5 -> 0 | AD5: =AA5-Q5 -> 0 | AE5: =AC5/Y5 -> #DIV/0! | AF5: =AD5/AA5 -> #DIV/0!
B6: =EOMONTH(A6,0) -> 31 | J6: =U6 -> 0 | K6: =L6/J6 -> #DIV/0! | N6: =L6-M6 -> 0 | O6: =P6/J6 -> #DIV/0! | Q6: =N6+P6 -> 0 | V6: =W6/U6 -> #DIV/0! | Y6: =W6-X6 -> 0 | AA6: =Y6-Z6 -> 0 | AC6: =Y6-N6 -> 0 | AD6: =AA6-Q6 -> 0 | AE6: =AC6/Y6 -> #DIV/0! | AF6: =AD6/AA6 -> #DIV/0!
B7: =EOMONTH(A7,0) -> 31 | J7: =U7 -> 0 | K7: =L7/J7 -> #DIV/0! | N7: =L7-M7 -> 0 | O7: =P7/J7 -> #DIV/0! | Q7: =N7+P7 -> 0 | V7: =W7/U7 -> #DIV/0! | Y7: =W7-X7 -> 0 | AA7: =Y7-Z7 -> 0 | AC7: =Y7-N7 -> 0 | AD7: =AA7-Q7 -> 0 | AE7: =AC7/Y7 -> #DIV/0! | AF7: =AD7/AA7 -> #DIV/0!
B8: =EOMONTH(A8,0) -> 31 | J8: =U8 -> 0 | K8: =L8/J8 -> #DIV/0! | N8: =L8-M8 -> 0 | O8: =P8/J8 -> #DIV/0! | Q8: =N8+P8 -> 0 | V8: =W8/U8 -> #DIV/0! | Y8: =W8-X8 -> 0 | AA8: =Y8-Z8 -> 0 | AC8: =Y8-N8 -> 0 | AD8: =AA8-Q8 -> 0 | AE8: =AC8/Y8 -> #DIV/0! | AF8: =AD8/AA8 -> #DIV/0!
B9: =EOMONTH(A9,0) -> 31 | J9: =U9 -> 0 | K9: =L9/J9 -> #DIV/0! | N9: =L9-M9 -> 0 | O9: =P9/J9 -> #DIV/0! | Q9: =N9+P9 -> 0 | V9: =W9/U9 -> #DIV/0! | Y9: =W9-X9 -> 0 | AA9: =Y9-Z9 -> 0 | AC9: =Y9-N9 -> 0 | AD9: =AA9-Q9 -> 0 | AE9: =AC9/Y9 -> #DIV/0! | AF9: =AD9/AA9 -> #DIV/0!
B10: =EOMONTH(A10,0) -> 31 | J10: =U10 -> 0 | K10: =L10/J10 -> #DIV/0! | N10: =L10-M10 -> 0 | O10: =P10/J10 -> #DIV/0! | Q10: =N10+P10 -> 0 | V10: =W10/U10 -> #DIV/0! | Y10: =W10-X10 -> 0 | AA10: =Y10-Z10 -> 0 | AC10: =Y10-N10 -> 0 | AD10: =AA10-Q10 -> 0 | AE10: =AC10/Y10 -> #DIV/0! | AF10: =AD10/AA10 -> #DIV/0!
B11: =EOMONTH(A11,0) -> 31 | J11: =U11 -> 0 | K11: =L11/J11 -> #DIV/0! | N11: =L11-M11 -> 0 | O11: =P11/J11 -> #DIV/0! | Q11: =N11+P11 -> 0 | V11: =W11/U11 -> #DIV/0! | Y11: =W11-X11 -> 0 | AA11: =Y11-Z11 -> 0 | AC11: =Y11-N11 -> 0 | AD11: =AA11-Q11 -> 0 | AE11: =AC11/Y11 -> #DIV/0! | AF11: =AD11/AA11 -> #DIV/0!
B12: =EOMONTH(A12,0) -> 31 | J12: =U12 -> 0 | K12: =L12/J12 -> #DIV/0! | N12: =L12-M12 -> 0 | O12: =P12/J12 -> #DIV/0! | Q12: =N12+P12 -> 0 | V12: =W12/U12 -> #DIV/0! | Y12: =W12-X12 -> 0 | AA12: =Y12-Z12 -> 0 | AC12: =Y12-N12 -> 0 | AD12: =AA12-Q12 -> 0 | AE12: =AC12/Y12 -> #DIV/0! | AF12: =AD12/AA12 -> #DIV/0!
B13: =EOMONTH(A13,0) -> 31 | J13: =U13 -> 0 | K13: =L13/J13 -> #DIV/0! | N13: =L13-M13 -> 0 | O13: =P13/J13 -> #DIV/0! | Q13: =N13+P13 -> 0 | V13: =W13/U13 -> #DIV/0! | Y13: =W13-X13 -> 0 | AA13: =Y13-Z13 -> 0 | AC13: =Y13-N13 -> 0 | AD13: =AA13-Q13 -> 0 | AE13: =AC13/Y13 -> #DIV/0! | AF13: =AD13/AA13 -> #DIV/0!
B14: =EOMONTH(A14,0) -> 31 | J14: =U14 -> 0 | K14: =L14/J14 -> #DIV/0! | N14: =L14-M14 -> 0 | O14: =P14/J14 -> #DIV/0! | Q14: =N14+P14 -> 0 | V14: =W14/U14 -> #DIV/0! | Y14: =W14-X14 -> 0 | AA14: =Y14-Z14 -> 0 | AC14: =Y14-N14 -> 0 | AD14: =AA14-Q14 -> 0 | AE14: =AC14/Y14 -> #DIV/0! | AF14: =AD14/AA14 -> #DIV/0!
B15: =EOMONTH(A15,0) -> 31 | J15: =U15 -> 0 | K15: =L15/J15 -> #DIV/0! | N15: =L15-M15 -> 0 | O15: =P15/J15 -> #DIV/0! | Q15: =N15+P15 -> 0 | V15: =W15/U15 -> #DIV/0! | Y15: =W15-X15 -> 0 | AA15: =Y15-Z15 -> 0 | AC15: =Y15-N15 -> 0 | AD15: =AA15-Q15 -> 0 | AE15: =AC15/Y15 -> #DIV/0! | AF15: =AD15/AA15 -> #DIV/0!
B16: =EOMONTH(A16,0) -> 31 | J16: =U16 -> 0 | K16: =L16/J16 -> #DIV/0! | N16: =L16-M16 -> 0 | O16: =P16/J16 -> #DIV/0! | Q16: =N16+P16 -> 0 | V16: =W16/U16 -> #DIV/0! | Y16: =W16-X16 -> 0 | AA16: =Y16-Z16 -> 0 | AC16: =Y16-N16 -> 0 | AD16: =AA16-Q16 -> 0 | AE16: =AC16/Y16 -> #DIV/0! | AF16: =AD16/AA16 -> #DIV/0!
... B26: =EOMONTH(A26,0) -> 31 | J26: =U26 -> 0 | K26: =L26/J26 -> #DIV/0! | N26: =L26-M26 -> 0 | O26: =P26/J26 -> #DIV/0! | Q26: =N26+P26 -> 0 | V26: =W26/U26 -> #DIV/0! | Y26: =W26-X26 -> 0 | AA26: =Y26-Z26 -> 0 | AC26: =Y26-N26 -> 0 | AD26: =AA26-Q26 -> 0 | AE26: =AC26/Y26 -> #DIV/0! | AF26: =AD26/AA26 -> #DIV/0!
B27: =EOMONTH(A27,0) -> 31 | J27: =U27 -> 0 | K27: =L27/J27 -> #DIV/0! | N27: =L27-M27 -> 0 | O27: =P27/J27 -> #N/A | P27: =VLOOKUP(C27,'[1]Profit and Loss agt new'!$D$17:$E$52,2,) -> #N/A | Q27: =N27+P27 -> #N/A | V27: =W27/U27 -> #DIV/0! | Y27: =W27-X27 -> 0 | AA27: =Y27-Z27 -> 0 | AC27: =Y27-N27 -> 0 | AD27: =AA27-Q27 -> #N/A | AE27: =AC27/Y27 -> #DIV/0! | AF27: =AD27/AA27 -> #N/A
B28: =EOMONTH(A28,0) -> 31 | J28: =U28 -> 0 | K28: =L28/J28 -> #DIV/0! | N28: =L28-M28 -> 0 | O28: =P28/J28 -> #DIV/0! | Q28: =N28+P28 -> 0 | V28: =W28/U28 -> #DIV/0! | Y28: =W28-X28 -> 0 | AA28: =Y28-Z28 -> 0 | AC28: =Y28-N28 -> 0 | AD28: =AA28-Q28 -> 0 | AE28: =AC28/Y28 -> #DIV/0! | AF28: =AD28/AA28 -> #DIV/0!
B29: =EOMONTH(A29,0) -> 31 | J29: =U29 -> 0 | K29: =L29/J29 -> #DIV/0! | N29: =L29-M29 -> 0 | O29: =P29/J29 -> #DIV/0! | Q29: =N29+P29 -> 0 | V29: =W29/U29 -> #DIV/0! | Y29: =W29-X29 -> 0 | AA29: =Y29-Z29 -> 0 | AC29: =Y29-N29 -> 0 | AD29: =AA29-Q29 -> 0 | AE29: =AC29/Y29 -> #DIV/0! | AF29: =AD29/AA29 -> #DIV/0!
B30: =EOMONTH(A30,0) -> 31 | J30: =U30 -> 0 | K30: =L30/J30 -> #DIV/0! | N30: =L30-M30 -> 0 | O30: =P30/J30 -> #DIV/0! | Q30: =N30+P30 -> 0 | V30: =W30/U30 -> #DIV/0! | Y30: =W30-X30 -> 0 | AA30: =Y30-Z30 -> 0 | AC30: =Y30-N30 -> 0 | AD30: =AA30-Q30 -> 0 | AE30: =AC30/Y30 -> #DIV/0! | AF30: =AD30/AA30 -> #DIV/0!
B31: =EOMONTH(A31,0) -> 31 | J31: =U31 -> 0 | K31: =L31/J31 -> #DIV/0! | N31: =L31-M31 -> 0 | O31: =P31/J31 -> #DIV/0! | Q31: =N31+P31 -> 0 | V31: =W31/U31 -> #DIV/0! | Y31: =W31-X31 -> 0 | AA31: =Y31-Z31 -> 0 | AC31: =Y31-N31 -> 0 | AD31: =AA31-Q31 -> 0 | AE31: =AC31/Y31 -> #DIV/0! | AF31: =AD31/AA31 -> #DIV/0!
B32: =EOMONTH(A32,0) -> 31 | J32: =U32 -> 0 | K32: =L32/J32 -> #DIV/0! | N32: =L32-M32 -> 0 | O32: =P32/J32 -> #DIV/0! | Q32: =N32+P32 -> 0 | V32: =W32/U32 -> #DIV/0! | Y32: =W32-X32 -> 0 | AA32: =Y32-Z32 -> 0 | AC32: =Y32-N32 -> 0 | AD32: =AA32-Q32 -> 0 | AE32: =AC32/Y32 -> #DIV/0! | AF32: =AD32/AA32 -> #DIV/0!
B33: =EOMONTH(A33,0) -> 31 | J33: =U33 -> 0 | K33: =L33/J33 -> #DIV/0! | N33: =L33-M33 -> 0 | O33: =P33/J33 -> #DIV/0! | Q33: =N33+P33 -> 0 | V33: =W33/U33 -> #DIV/0! | Y33: =W33-X33 -> 0 | AA33: =Y33-Z33 -> 0 | AC33: =Y33-N33 -> 0 | AD33: =AA33-Q33 -> 0 | AE33: =AC33/Y33 -> #DIV/0! | AF33: =AD33/AA33 -> #DIV/0!
B34: =EOMONTH(A34,0) -> 31 | J34: =U34 -> 0 | K34: =L34/J34 -> #DIV/0! | N34: =L34-M34 -> 0 | O34: =P34/J34 -> #DIV/0! | Q34: =N34+P34 -> 0 | V34: =W34/U34 -> #DIV/0! | Y34: =W34-X34 -> 0 | AA34: =Y34-Z34 -> 0 | AC34: =Y34-N34 -> 0 | AD34: =AA34-Q34 -> 0 | AE34: =AC34/Y34 -> #DIV/0! | AF34: =AD34/AA34 -> #DIV/0!
B35: =EOMONTH(A35,0) -> 31 | J35: =U35 -> 0 | K35: =L35/J35 -> #DIV/0! | N35: =L35-M35 -> 0 | O35: =P35/J35 -> #DIV/0! | Q35: =N35+P35 -> 0 | V35: =W35/U35 -> #DIV/0! | Y35: =W35-X35 -> 0 | AA35: =Y35-Z35 -> 0 | AC35: =Y35-N35 -> 0 | AD35: =AA35-Q35 -> 0 | AE35: =AC35/Y35 -> #DIV/0! | AF35: =AD35/AA35 -> #DIV/0!
B36: =EOMONTH(A36,0) -> 31 | J36: =U36 -> 0 | K36: =L36/J36 -> #DIV/0! | N36: =L36-M36 -> 0 | O36: =P36/J36 -> #DIV/0! | Q36: =N36+P36 -> 0 | V36: =W36/U36 -> #DIV/0! | Y36: =W36-X36 -> 0 | AA36: =Y36-Z36 -> 0 | AC36: =Y36-N36 -> 0 | AD36: =AA36-Q36 -> 0 | AE36: =AC36/Y36 -> #DIV/0! | AF36: =AD36/AA36 -> #DIV/0!
B37: =EOMONTH(A37,0) -> 31 | J37: =U37 -> 0 | K37: =L37/J37 -> #DIV/0! | N37: =L37-M37 -> 0 | O37: =P37/J37 -> #DIV/0! | Q37: =N37+P37 -> 0 | V37: =W37/U37 -> #DIV/0! | Y37: =W37-X37 -> 0 | AA37: =Y37-Z37 -> 0 | AC37: =Y37-N37 -> 0 | AD37: =AA37-Q37 -> 0 | AE37: =AC37/Y37 -> #DIV/0! | AF37: =AD37/AA37 -> #DIV/0!
B38: =EOMONTH(A38,0) -> 31 | J38: =U38 -> 0 | K38: =L38/J38 -> #DIV/0! | N38: =L38-M38 -> 0 | O38: =P38/J38 -> #DIV/0! | Q38: =N38+P38 -> 0 | V38: =W38/U38 -> #DIV/0! | Y38: =W38-X38 -> 0 | AA38: =Y38-Z38 -> 0 | AC38: =Y38-N38 -> 0 | AD38: =AA38-Q38 -> 0 | AE38: =AC38/Y38 -> #DIV/0! | AF38: =AD38/AA38 -> #DIV/0!
B39: =EOMONTH(A39,0) -> 31 | J39: =U39 -> 0 | K39: =L39/J39 -> #DIV/0! | N39: =L39-M39 -> 0 | O39: =P39/J39 -> #DIV/0! | Q39: =N39+P39 -> 0 | V39: =W39/U39 -> #DIV/0! | Y39: =W39-X39 -> 0 | AA39: =Y39-Z39 -> 0 | AC39: =Y39-N39 -> 0 | AD39: =AA39-Q39 -> 0 | AE39: =AC39/Y39 -> #DIV/0! | AF39: =AD39/AA39 -> #DIV/0!
... B76: =EOMONTH(A76,0) -> 31 | J76: =U76 -> 0 | K76: =L76/J76 -> #DIV/0! | N76: =L76-M76 -> 0 | O76: =P76/J76 -> #DIV/0! | Q76: =N76+P76 -> 0 | V76: =W76/U76 -> #DIV/0! | Y76: =W76-X76 -> 0 | AA76: =Y76-Z76 -> 0 | AC76: =Y76-N76 -> 0 | AD76: =AA76-Q76 -> 0 | AE76: =AC76/Y76 -> #DIV/0! | AF76: =AD76/AA76 -> #DIV/0!
B77: =EOMONTH(A77,0) -> 31 | J77: =U77 -> 0 | K77: =L77/J77 -> #DIV/0! | N77: =L77-M77 -> 0 | O77: =P77/J77 -> #N/A | P77: =VLOOKUP(C77,'[1]Profit and Loss agt new'!$D$17:$E$52,2,) -> #N/A | Q77: =N77+P77 -> #N/A | V77: =W77/U77 -> #DIV/0! | Y77: =W77-X77 -> 0 | AA77: =Y77-Z77 -> 0 | AC77: =Y77-N77 -> 0 | AD77: =AA77-Q77 -> #N/A | AE77: =AC77/Y77 -> #DIV/0! | AF77: =AD77/AA77 -> #N/A
B78: =EOMONTH(A78,0) -> 31 | J78: =U78 -> 0 | K78: =L78/J78 -> #DIV/0! | N78: =L78-M78 -> 0 | O78: =P78/J78 -> #DIV/0! | Q78: =N78+P78 -> 0 | V78: =W78/U78 -> #DIV/0! | Y78: =W78-X78 -> 0 | AA78: =Y78-Z78 -> 0 | AC78: =Y78-N78 -> 0 | AD78: =AA78-Q78 -> 0 | AE78: =AC78/Y78 -> #DIV/0! | AF78: =AD78/AA78 -> #DIV/0!
B79: =EOMONTH(A79,0) -> 31 | J79: =U79 -> 0 | K79: =L79/J79 -> #DIV/0! | N79: =L79-M79 -> 0 | O79: =P79/J79 -> #DIV/0! | Q79: =N79+P79 -> 0 | V79: =W79/U79 -> #DIV/0! | Y79: =W79-X79 -> 0 | AA79: =Y79-Z79 -> 0 | AC79: =Y79-N79 -> 0 | AD79: =AA79-Q79 -> 0 | AE79: =AC79/Y79 -> #DIV/0! | AF79: =AD79/AA79 -> #DIV/0!
B80: =EOMONTH(A80,0) -> 31 | J80: =U80 -> 0 | K80: =L80/J80 -> #DIV/0! | N80: =L80-M80 -> 0 | O80: =P80/J80 -> #DIV/0! | Q80: =N80+P80 -> 0 | V80: =W80/U80 -> #DIV/0! | Y80: =W80-X80 -> 0 | AA80: =Y80-Z80 -> 0 | AC80: =Y80-N80 -> 0 | AD80: =AA80-Q80 -> 0 | AE80: =AC80/Y80 -> #DIV/0! | AF80: =AD80/AA80 -> #DIV/0!
B81: =EOMONTH(A81,0) -> 31 | J81: =U81 -> 0 | K81: =L81/J81 -> #DIV/0! | N81: =L81-M81 -> 0 | O81: =P81/J81 -> #DIV/0! | Q81: =N81+P81 -> 0 | V81: =W81/U81 -> #DIV/0! | Y81: =W81-X81 -> 0 | AA81: =Y81-Z81 -> 0 | AC81: =Y81-N81 -> 0 | AD81: =AA81-Q81 -> 0 | AE81: =AC81/Y81 -> #DIV/0! | AF81: =AD81/AA81 -> #DIV/0!
B82: =EOMONTH(A82,0) -> 31 | J82: =U82 -> 0 | K82: =L82/J82 -> #DIV/0! | N82: =L82-M82 -> 0 | O82: =P82/J82 -> #DIV/0! | Q82: =N82+P82 -> 0 | V82: =W82/U82 -> #DIV/0! | Y82: =W82-X82 -> 0 | AA82: =Y82-Z82 -> 0 | AC82: =Y82-N82 -> 0 | AD82: =AA82-Q82 -> 0 | AE82: =AC82/Y82 -> #DIV/0! | AF82: =AD82/AA82 -> #DIV/0!
B83: =EOMONTH(A83,0) -> 31 | J83: =U83 -> 0 | K83: =L83/J83 -> #DIV/0! | N83: =L83-M83 -> 0 | O83: =P83/J83 -> #DIV/0! | Q83: =N83+P83 -> 0 | V83: =W83/U83 -> #DIV/0! | Y83: =W83-X83 -> 0 | AA83: =Y83-Z83 -> 0 | AC83: =Y83-N83 -> 0 | AD83: =AA83-Q83 -> 0 | AE83: =AC83/Y83 -> #DIV/0! | AF83: =AD83/AA83 -> #DIV/0!
B84: =EOMONTH(A84,0) -> 31 | J84: =U84 -> 0 | K84: =L84/J84 -> #DIV/0! | N84: =L84-M84 -> 0 | O84: =P84/J84 -> #DIV/0! | Q84: =N84+P84 -> 0 | V84: =W84/U84 -> #DIV/0! | Y84: =W84-X84 -> 0 | AA84: =Y84-Z84 -> 0 | AC84: =Y84-N84 -> 0 | AD84: =AA84-Q84 -> 0 | AE84: =AC84/Y84 -> #DIV/0! | AF84: =AD84/AA84 -> #DIV/0!
B85: =EOMONTH(A85,0) -> 31 | J85: =U85 -> 0 | K85: =L85/J85 -> #DIV/0! | N85: =L85-M85 -> 0 | O85: =P85/J85 -> #DIV/0! | Q85: =N85+P85 -> 0 | V85: =W85/U85 -> #DIV/0! | Y85: =W85-X85 -> 0 | AA85: =Y85-Z85 -> 0 | AC85: =Y85-N85 -> 0 | AD85: =AA85-Q85 -> 0 | AE85: =AC85/Y85 -> #DIV/0! | AF85: =AD85/AA85 -> #DIV/0!
...

Sheet BS
B1: Aspirarch Market Platforms Private Limited | AG1: AGT | AH1: 42897872
B2: Balance Sheet | J2: 1 | Q2: 1 | AG2: AL | AH2: 38110854
B3: As on 31st October 2024 | C3: Expora | D3: Expora | E3: Expora | F3: Expora | G3: Expora | H3: Expora | I3: Expora | J3: AGT | K3: AGT | L3: AGT | M3: AGT | N3: AGT | O3: AGT | P3: AGT | Q3: Lanka | R3: Lanka | S3: Lanka | T3: Lanka | U3: Lanka | V3: Lanka | W3: Lanka | X3: Conso | Y3: Conso | Z3: Conso | AA3: Conso | AB3: Conso | AC3: Conso | AD3: Conso
B4: Currency (Rs) | C4: Apr-25 | D4: 45778 | E4: 45809 | F4: 45839 | G4: 45870 | H4: 45901 | I4: 45931 | J4: Apr-25 | K4: 45778 | L4: 45809 | M4: 45839 | N4: 45870 | O4: 45901 | P4: 45931 | Q4: Apr-25 | R4: 45778 | S4: 45809 | T4: 45839 | U4: 45870 | V4: 45901 | W4: 45931 | X4: Apr-25 | Y4: 45778 | Z4: 45809 | AA4: 45839 | AB4: 45870 | AC4: 45901 | AD4: 45931 | AE4: Elimination | AF4: YTD Console Net | AH4: Remarks
B5: Fixed assets -Tangible | C5: =SUMIFS(#REF!,#REF!,B5) -> #REF! | D5: =SUMIFS(#REF!,#REF!,B5) -> #REF! | E5: =SUMIFS(#REF!,#REF!,B5) -> #REF! | F5: =SUMIFS(#REF!,#REF!,B5) -> #REF! | G5: =SUMIFS(#REF!,#REF!,B5) -> #REF! | H5: =SUMIFS(#REF!,#REF!,B5) -> #REF! | I5: =SUMIFS(#REF!,#REF!,B5) -> #REF! | J5: =SUMIFS('AGT TB Apr -25'!M:M,'AGT TB Apr -25'!S:S,BS!B5)*$J$2 -> 0 | Q5: =SUMIFS(#REF!,#REF!,BS!B5)*$Q$2 -> #REF! | X5: =C5+J5+Q5 -> #REF! | Y5: =D5+K5+R5 -> #REF! | Z5: =E5+L5+S5 -> #REF! | AA5: =F5+M5+T5 -> #REF! | AB5: =G5+N5+U5 -> #REF! | AC5: =H5+O5+V5 -> #REF! | AD5: =I5+P5+W5 -> #REF! | AF5: =X5-AE5 -> #REF! | AH5: Refer BS Annexure- BS4
B6: Fixed assets -Intangible | C6: =SUMIFS(#REF!,#REF!,B6) -> #REF! | D6: =SUMIFS(#REF!,#REF!,B6) -> #REF! | E6: =SUMIFS(#REF!,#REF!,B6) -> #REF! | F6: =SUMIFS(#REF!,#REF!,B6) -> #REF! | G6: =SUMIFS(#REF!,#REF!,B6) -> #REF! | H6: =SUMIFS(#REF!,#REF!,B6) -> #REF! | I6: =SUMIFS(#REF!,#REF!,B6) -> #REF! | J6: =SUMIFS('AGT TB Apr -25'!M:M,'AGT TB Apr -25'!S:S,BS!B6)*$J$2 -> 0 | K6: 0 | L6: 0 | M6: 0 | N6: 0 | O6: 0 | P6: =SUMIF(#REF!,B6,#REF!) -> #REF! | Q6: =SUMIFS(#REF!,#REF!,BS!B6)*$Q$2 -> #REF! | X6: =C6+J6+Q6 -> #REF! | Y6: =D6+K6+R6 -> #REF! | Z6: =E6+L6+S6 -> #REF! | AA6: =F6+M6+T6 -> #REF! | AB6: =G6+N6+U6 -> #REF! | AC6: =H6+O6+V6 -> #REF! | AD6: =I6+P6+W6 -> #REF! | AF6: =X6-AE6 -> #REF!
B7: Investments in Subsidiary | C7: =SUM(C8:C11) -> #REF! | D7: =SUM(D8:D11) -> #REF! | E7: =SUM(E8:E11) -> #REF! | F7: =SUM(F8:F11) -> #REF! | G7: =SUM(G8:G11) -> #REF! | H7: =SUM(H8:H11) -> #REF! | I7: =SUM(I8:I11) -> #REF! | J7: =SUM(J8:J11) -> 0 | ... Q7: =SUM(Q8:Q11) -> #REF! | X7: =SUM(X8:X11) -> #REF! | Y7: =SUM(Y8:Y11) -> #REF! | Z7: =SUM(Z8:Z11) -> #REF! | AA7: =SUM(AA8:AA11) -> #REF! | AB7: =SUM(AB8:AB11) -> #REF! | AC7: =SUM(AC8:AC11) -> #REF! | AD7: =SUM(AD8:AD11) -> #REF! | AF7: =SUM(AF8:AF11) -> #REF! | AH7: Refer BS Annexure- BS4
B8: Investment in Parnia Expora Pvt Ltd | C8: =SUMIFS(#REF!,#REF!,B8) -> #REF! | D8: =SUMIFS(#REF!,#REF!,B8) -> #REF! | E8: =SUMIFS(#REF!,#REF!,B8) -> #REF! | F8: =SUMIFS(#REF!,#REF!,B8) -> #REF! | G8: =SUMIFS(#REF!,#REF!,B8) -> #REF! | H8: =SUMIFS(#REF!,#REF!,B8) -> #REF! | I8: =SUMIFS(#REF!,#REF!,B8) -> #REF! | J8: =SUMIFS('AGT TB Apr -25'!M:M,'AGT TB Apr -25'!S:S,BS!B8)*$J$2 -> 0 | K8: =SUMIF(#REF!,B:B,#REF!) -> #REF! | L8: =SUMIF(#REF!,B:B,#REF!) -> #REF! | M8: =SUMIF(#REF!,BS!B:B,#REF!) -> #REF! | N8: =SUMIF(#REF!,B8,#REF!) -> #REF! | O8: =SUMIF(#REF!,B:B,#REF!) -> #REF! | P8: =SUMIF(#REF!,B8,#REF!) -> #REF! | Q8: =SUMIFS(#REF!,#REF!,BS!B8)*$Q$2 -> #REF! | X8: =C8+J8+Q8 -> #REF! | Y8: =D8+K8+R8 -> #REF! | Z8: =E8+L8+S8 -> #REF! | AA8: =F8+M8+T8 -> #REF! | AB8: =G8+N8+U8 -> #REF! | AC8: =H8+O8+V8 -> #REF! | AD8: =I8+P8+W8 -> #REF! | AF8: =X8-AE8 -> #REF! | AH8: 100% Investment in Parnia Expora Pvt Ltd. Share Certificate Received.
B9: Investment in Arha Platforms Genral Trading LLC | C9: =SUMIFS(#REF!,#REF!,B9) -> #REF! | D9: =SUMIFS(#REF!,#REF!,B9) -> #REF! | E9: =SUMIFS(#REF!,#REF!,B9) -> #REF! | F9: =SUMIFS(#REF!,#REF!,B9) -> #REF! | G9: =SUMIFS(#REF!,#REF!,B9) -> #REF! | H9: =SUMIFS(#REF!,#REF!,B9) -> #REF! | I9: =SUMIFS(#REF!,#REF!,B9) -> #REF! | J9: =SUMIFS('AGT TB Apr -25'!M:M,'AGT TB Apr -25'!S:S,BS!B9)*$J$2 -> 0 | K9: =SUMIF(#REF!,B:B,#REF!) -> #REF! | L9: =SUMIF(#REF!,B:B,#REF!) -> #REF! | M9: =SUMIF(#REF!,BS!B:B,#REF!) -> #REF! | N9: =SUMIF(#REF!,B9,#REF!) -> #REF! | O9: =SUMIF(#REF!,B:B,#REF!) -> #REF! | P9: =SUMIF(#REF!,B9,#REF!) -> #REF! | Q9: =SUMIFS(#REF!,#REF!,BS!B9)*$Q$2 -> #REF! | X9: =C9+J9+Q9 -> #REF! | Y9: =D9+K9+R9 -> #REF! | Z9: =E9+L9+S9 -> #REF! | AA9: =F9+M9+T9 -> #REF! | AB9: =G9+N9+U9 -> #REF! | AC9: =H9+O9+V9 -> #REF! | AD9: =I9+P9+W9 -> #REF! | AE9: =C9 -> #REF! | AF9: =X9-AE9 -> #REF! | AH9: 100% Investment in Arha General Trading LLC
B10: Investment in AMI AGRO | C10: =SUMIFS(#REF!,#REF!,B10) -> #REF! | D10: =SUMIFS(#REF!,#REF!,B10) -> #REF! | E10: =SUMIFS(#REF!,#REF!,B10) -> #REF! | F10: =SUMIFS(#REF!,#REF!,B10) -> #REF! | G10: =SUMIFS(#REF!,#REF!,B10) -> #REF! | H10: =SUMIFS(#REF!,#REF!,B10) -> #REF! | I10: =SUMIFS(#REF!,#REF!,B10) -> #REF! | J10: =SUMIFS('AGT TB Apr -25'!M:M,'AGT TB Apr -25'!S:S,BS!B10)*$J$2 -> 0 | K10: =SUMIF(#REF!,B:B,#REF!) -> #REF! | L10: =SUMIF(#REF!,B:B,#REF!) -> #REF! | M10: =SUMIF(#REF!,BS!B:B,#REF!) -> #REF! | N10: =SUMIF(#REF!,B10,#REF!) -> #REF! | O10: =SUMIF(#REF!,B:B,#REF!) -> #REF! | P10: =SUMIF(#REF!,B10,#REF!) -> #REF! | Q10: =SUMIFS(#REF!,#REF!,BS!B10)*$Q$2 -> #REF! | X10: =C10+J10+Q10 -> #REF! | Y10: =D10+K10+R10 -> #REF! | Z10: =E10+L10+S10 -> #REF! | AA10: =F10+M10+T10 -> #REF! | AB10: =G10+N10+U10 -> #REF! | AC10: =H10+O10+V10 -> #REF! | AD10: =I10+P10+W10 -> #REF! | AE10: =C10 -> #REF! | AF10: =X10-AE10 -> #REF!
B11: Investment in Arha Platforms Jewellery Trading LLC | C11: =SUMIFS(#REF!,#REF!,B11) -> #REF! | D11: =SUMIFS(#REF!,#REF!,B11) -> #REF! | E11: =SUMIFS(#REF!,#REF!,B11) -> #REF! | F11: =SUMIFS(#REF!,#REF!,B11) -> #REF! | G11: =SUMIFS(#REF!,#REF!,B11) -> #REF! | H11: =SUMIFS(#REF!,#REF!,B11) -> #REF! | I11: =SUMIFS(#REF!,#REF!,B11) -> #REF! | J11: =SUMIFS('AGT TB Apr -25'!M:M,'AGT TB Apr -25'!S:S,BS!B11)*$J$2 -> 0 | K11: =SUMIF(#REF!,B:B,#REF!) -> #REF! | L11: =SUMIF(#REF!,B:B,#REF!) -> #REF! | M11: =SUMIF(#REF!,BS!B:B,#REF!) -> #REF! | N11: =SUMIF(#REF!,B11,#REF!) -> #REF! | O11: =SUMIF(#REF!,B:B,#REF!) -> #REF! | P11: =SUMIF(#REF!,B11,#REF!) -> #REF! | Q11: =SUMIFS(#REF!,#REF!,BS!B11)*$Q$2 -> #REF! | X11: =C11+J11+Q11 -> #REF! | Y11: =D11+K11+R11 -> #REF! | Z11: =E11+L11+S11 -> #REF! | AA11: =F11+M11+T11 -> #REF! | AB11: =G11+N11+U11 -> #REF! | AC11: =H11+O11+V11 -> #REF! | AD11: =I11+P11+W11 -> #REF! | AF11: =X11-AE11 -> #REF! | AH11: 100% Investment in Arha Jewellery Trading LLC
B12: Bank Balance | C12: =SUMIFS(#REF!,#REF!,B12) -> #REF! | D12: =SUMIFS(#REF!,#REF!,B12) -> #REF! | E12: =SUMIFS(#REF!,#REF!,B12) -> #REF! | F12: =SUMIFS(#REF!,#REF!,B12) -> #REF! | G12: =SUMIFS(#REF!,#REF!,B12) -> #REF! | H12: =SUMIFS(#REF!,#REF!,B12) -> #REF! | I12: =SUMIFS(#REF!,#REF!,B12) -> #REF! | J12: =SUMIFS('AGT TB Apr -25'!M:M,'AGT TB Apr -25'!S:S,BS!B12)*$J$2 -> 0 | Q12: =SUMIFS(#REF!,#REF!,BS!B12)*$Q$2 -> #REF! | X12: =C12+J12+Q12 -> #REF! | Y12: =D12+K12+R12 -> #REF! | Z12: =E12+L12+S12 -> #REF! | AA12: =F12+M12+T12 -> #REF! | AB12: =G12+N12+U12 -> #REF! | AC12: =H12+O12+V12 -> #REF! | AD12: =I12+P12+W12 -> #REF! | AF12: =X12-AE12 -> #REF!
B13: Cash Balance | C13: =SUMIFS(#REF!,#REF!,B13) -> #REF! | D13: =SUMIFS(#REF!,#REF!,B13) -> #REF! | E13: =SUMIFS(#REF!,#REF!,B13) -> #REF! | F13: =SUMIFS(#REF!,#REF!,B13) -> #REF! | G13: =SUMIFS(#REF!,#REF!,B13) -> #REF! | H13: =SUMIFS(#REF!,#REF!,B13) -> #REF! | I13: =SUMIFS(#REF!,#REF!,B13) -> #REF! | J13: =SUMIFS('AGT TB Apr -25'!M:M,'AGT TB Apr -25'!S:S,BS!B13)*$J$2 -> 0 | Q13: =SUMIFS(#REF!,#REF!,BS!B13)*$Q$2 -> #REF! | X13: =C13+J13+Q13 -> #REF! | Y13: =D13+K13+R13 -> #REF! | Z13: =E13+L13+S13 -> #REF! | AA13: =F13+M13+T13 -> #REF! | AB13: =G13+N13+U13 -> #REF! | AC13: =H13+O13+V13 -> #REF! | AD13: =I13+P13+W13 -> #REF! | AF13: =X13-AE13 -> #REF!
B14: Closing Stock | C14: =SUMIFS(#REF!,#REF!,B14) -> #REF! | D14: =SUMIFS(#REF!,#REF!,B14) -> #REF! | E14: =SUMIFS(#REF!,#REF!,B14) -> #REF! | F14: =SUMIFS(#REF!,#REF!,B14) -> #REF! | G14: =SUMIFS(#REF!,#REF!,B14) -> #REF! | H14: =SUMIFS(#REF!,#REF!,B14) -> #REF! | I14: =SUMIFS(#REF!,#REF!,B14) -> #REF! | J14: =SUMIFS('AGT TB Apr -25'!M:M,'AGT TB Apr -25'!S:S,BS!B14)*$J$2 -> 0 | Q14: =SUMIFS(#REF!,#REF!,BS!B14)*$Q$2 -> #REF! | X14: =C14+J14+Q14 -> #REF! | Y14: =D14+K14+R14 -> #REF! | Z14: =E14+L14+S14 -> #REF! | AA14: =F14+M14+T14 -> #REF! | AB14: =G14+N14+U14 -> #REF! | AC14: =H14+O14+V14 -> #REF! | AD14: =I14+P14+W14 -> #REF! | AF14: =X14-AE14 -> #REF! | AH14: Refer BS Annexure- BS2
B15: Trade Receivables | C15: =SUMIFS(#REF!,#REF!,B15) -> #REF! | D15: =SUMIFS(#REF!,#REF!,B15) -> #REF! | E15: =SUMIFS(#REF!,#REF!,B15) -> #REF! | F15: =SUMIFS(#REF!,#REF!,B15) -> #REF! | G15: =SUMIFS(#REF!,#REF!,B15) -> #REF! | H15: =SUMIFS(#REF!,#REF!,B15) -> #REF! | I15: =SUMIFS(#REF!,#REF!,B15) -> #REF! | J15: =SUMIFS('AGT TB Apr -25'!M:M,'AGT TB Apr -25'!S:S,BS!B15)*$J$2 -> 0 | Q15: =SUMIFS(#REF!,#REF!,BS!B15)*$Q$2 -> #REF! | X15: =C15+J15+Q15 -> #REF! | Y15: =D15+K15+R15 -> #REF! | Z15: =E15+L15+S15 -> #REF! | AA15: =F15+M15+T15 -> #REF! | AB15: =G15+N15+U15 -> #REF! | AC15: =H15+O15+V15 -> #REF! | AD15: =I15+P15+W15 -> #REF! | AE15: =AH2+AH1 -> 81008725 | AF15: =X15-AE15 -> #REF! | AH15: Refer Trade Receivable Annexure- BS1
B16: Other Current Asset | C16: =SUM(C17:C32) -> #REF! | D16: =SUM(D17:D32) -> #REF! | E16: =SUM(E17:E32) -> #REF! | F16: =SUM(F17:F32) -> #REF! | G16: =SUM(G17:G32) -> #REF! | H16: =SUM(H17:H32) -> #REF! | I16: =SUM(I17:I32) -> #REF! | J16: =SUM(J17:J32) -> 0 | Q16: =SUM(Q17:Q32) -> #REF! | X16: =SUM(X17:X32) -> #REF! | Y16: =SUM(Y17:Y32) -> #REF! | Z16: =SUM(Z17:Z32) -> #REF! | AA16: =SUM(AA17:AA32) -> #REF! | AB16: =SUM(AB17:AB32) -> #REF! | AC16: =SUM(AC17:AC32) -> #REF! | AD16: =SUM(AD17:AD32) -> #REF! | AF16: =SUM(AF17:AF32) -> #REF! | AH16: Refer BS Annexure - BS1
B17: Term Deposits | C17: =SUMIFS(#REF!,#REF!,B17) -> #REF! | D17: =SUMIFS(#REF!,#REF!,B17) -> #REF! | E17: =SUMIFS(#REF!,#REF!,B17) -> #REF! | F17: =SUMIFS(#REF!,#REF!,B17) -> #REF! | G17: =SUMIFS(#REF!,#REF!,B17) -> #REF! | H17: =SUMIFS(#REF!,#REF!,B17) -> #REF! | I17: =SUMIFS(#REF!,#REF!,B17) -> #REF! | J17: =SUMIFS('AGT TB Apr -25'!M:M,'AGT TB Apr -25'!S:S,BS!B17)*$J$2 -> 0 | Q17: =SUMIFS(#REF!,#REF!,BS!B17)*$Q$2 -> #REF! | X17: =C17+J17+Q17 -> #REF! | Y17: =D17+K17+R17 -> #REF! | Z17: =E17+L17+S17 -> #REF! | AA17: =F17+M17+T17 -> #REF! | AB17: =G17+N17+U17 -> #REF! | AC17: =H17+O17+V17 -> #REF! | AD17: =I17+P17+W17 -> #REF! | AF17: =X17-AE17 -> #REF!
B18: Interest on FD Receivable | C18: =SUMIFS(#REF!,#REF!,B18) -> #REF! | D18: =SUMIFS(#REF!,#REF!,B18) -> #REF! | E18: =SUMIFS(#REF!,#REF!,B18) -> #REF! | F18: =SUMIFS(#REF!,#REF!,B18) -> #REF! | G18: =SUMIFS(#REF!,#REF!,B18) -> #REF! | H18: =SUMIFS(#REF!,#REF!,B18) -> #REF! | I18: =SUMIFS(#REF!,#REF!,B18) -> #REF! | J18: =SUMIFS('AGT TB Apr -25'!M:M,'AGT TB Apr -25'!S:S,BS!B18)*$J$2 -> 0 | Q18: =SUMIFS(#REF!,#REF!,BS!B18)*$Q$2 -> #REF! | X18: =C18+J18+Q18 -> #REF! | Y18: =D18+K18+R18 -> #REF! | Z18: =E18+L18+S18 -> #REF! | AA18: =F18+M18+T18 -> #REF! | AB18: =G18+N18+U18 -> #REF! | AC18: =H18+O18+V18 -> #REF! | AD18: =I18+P18+W18 -> #REF! | AF18: =X18-AE18 -> #REF!
B19: TCS Receivable | C19: =SUMIFS(#REF!,#REF!,B19) -> #REF! | D19: =SUMIFS(#REF!,#REF!,B19) -> #REF! | E19: =SUMIFS(#REF!,#REF!,B19) -> #REF! | F19: =SUMIFS(#REF!,#REF!,B19) -> #REF! | G19: =SUMIFS(#REF!,#REF!,B19) -> #REF! | H19: =SUMIFS(#REF!,#REF!,B19) -> #REF! | I19: =SUMIFS(#REF!,#REF!,B19) -> #REF! | J19: =SUMIFS('AGT TB Apr -25'!M:M,'AGT TB Apr -25'!S:S,BS!B19)*$J$2 -> 0 | Q19: =SUMIFS(#REF!,#REF!,BS!B19)*$Q$2 -> #REF! | X19: =C19+J19+Q19 -> #REF! | Y19: =D19+K19+R19 -> #REF! | Z19: =E19+L19+S19 -> #REF! | AA19: =F19+M19+T19 -> #REF! | AB19: =G19+N19+U19 -> #REF! | AC19: =H19+O19+V19 -> #REF! | AD19: =I19+P19+W19 -> #REF! | AF19: =X19-AE19 -> #REF!
B20: TDS Receivable | C20: =SUMIFS(#REF!,#REF!,B20) -> #REF! | D20: =SUMIFS(#REF!,#REF!,B20) -> #REF! | E20: =SUMIFS(#REF!,#REF!,B20) -> #REF! | F20: =SUMIFS(#REF!,#REF!,B20) -> #REF! | G20: =SUMIFS(#REF!,#REF!,B20) -> #REF! | H20: =SUMIFS(#REF!,#REF!,B20) -> #REF! | I20: =SUMIFS(#REF!,#REF!,B20) -> #REF! | J20: =SUMIFS('AGT TB Apr -25'!M:M,'AGT TB Apr -25'!S:S,BS!B20)*$J$2 -> 0 | Q20: =SUMIFS(#REF!,#REF!,BS!B20)*$Q$2 -> #REF! | X20: =C20+J20+Q20 -> #REF! | Y20: =D20+K20+R20 -> #REF! | Z20: =E20+L20+S20 -> #REF! | AA20: =F20+M20+T20 -> #REF! | AB20: =G20+N20+U20 -> #REF! | AC20: =H20+O20+V20 -> #REF! | AD20: =I20+P20+W20 -> #REF! | AF20: =X20-AE20 -> #REF!
B21: Security Deposit | C21: =SUMIFS(#REF!,#REF!,B21) -> #REF! | D21: =SUMIFS(#REF!,#REF!,B21) -> #REF! | E21: =SUMIFS(#REF!,#REF!,B21) -> #REF! | F21: =SUMIFS(#REF!,#REF!,B21) -> #REF! | G21: =SUMIFS(#REF!,#REF!,B21) -> #REF! | H21: =SUMIFS(#REF!,#REF!,B21) -> #REF! | I21: =SUMIFS(#REF!,#REF!,B21) -> #REF! | J21: =SUMIFS('AGT TB Apr -25'!M:M,'AGT TB Apr -25'!S:S,BS!B21)*$J$2 -> 0 | Q21: =SUMIFS(#REF!,#REF!,BS!B21)*$Q$2 -> #REF! | X21: =C21+J21+Q21 -> #REF! | Y21: =D21+K21+R21 -> #REF! | Z21: =E21+L21+S21 -> #REF! | AA21: =F21+M21+T21 -> #REF! | AB21: =G21+N21+U21 -> #REF! | AC21: =H21+O21+V21 -> #REF! | AD21: =I21+P21+W21 -> #REF! | AF21: =X21-AE21 -> #REF!
B22: Rodtep Receivable | C22: =SUMIFS(#REF!,#REF!,B22) -> #REF! | D22: =SUMIFS(#REF!,#REF!,B22) -> #REF! | E22: =SUMIFS(#REF!,#REF!,B22) -> #REF! | F22: =SUMIFS(#REF!,#REF!,B22) -> #REF! | G22: =SUMIFS(#REF!,#REF!,B22) -> #REF! | H22: =SUMIFS(#REF!,#REF!,B22) -> #REF! | I22: =SUMIFS(#REF!,#REF!,B22) -> #REF! | J22: =SUMIFS('AGT TB Apr -25'!M:M,'AGT TB Apr -25'!S:S,BS!B22)*$J$2 -> 0 | Q22: =SUMIFS(#REF!,#REF!,BS!B22)*$Q$2 -> #REF! | X22: =C22+J22+Q22 -> #REF! | Y22: =D22+K22+R22 -> #REF! | Z22: =E22+L22+S22 -> #REF! | AA22: =F22+M22+T22 -> #REF! | AB22: =G22+N22+U22 -> #REF! | AC22: =H22+O22+V22 -> #REF! | AD22: =I22+P22+W22 -> #REF! | AF22: =X22-AE22 -> #REF!
B23: GST Input tax Assets | C23: =SUMIFS(#REF!,#REF!,B23) -> #REF! | D23: =SUMIFS(#REF!,#REF!,B23) -> #REF! | E23: =SUMIFS(#REF!,#REF!,B23) -> #REF! | F23: =SUMIFS(#REF!,#REF!,B23) -> #REF! | G23: =SUMIFS(#REF!,#REF!,B23) -> #REF! | H23: =SUMIFS(#REF!,#REF!,B23) -> #REF! | I23: =SUMIFS(#REF!,#REF!,B23) -> #REF! | J23: =SUMIFS('AGT TB Apr -25'!M:M,'AGT TB Apr -25'!S:S,BS!B23)*$J$2 -> 0 | Q23: =SUMIFS(#REF!,#REF!,BS!B23)*$Q$2 -> #REF! | X23: =C23+J23+Q23 -> #REF! | Y23: =D23+K23+R23 -> #REF! | Z23: =E23+L23+S23 -> #REF! | AA23: =F23+M23+T23 -> #REF! | AB23: =G23+N23+U23 -> #REF! | AC23: =H23+O23+V23 -> #REF! | AD23: =I23+P23+W23 -> #REF! | AF23: =X23-AE23 -> #REF!
B24: Prepaid Expenses | C24: =SUMIFS(#REF!,#REF!,B24) -> #REF! | D24: =SUMIFS(#REF!,#REF!,B24) -> #REF! | E24: =SUMIFS(#REF!,#REF!,B24) -> #REF! | F24: =SUMIFS(#REF!,#REF!,B24) -> #REF! | G24: =SUMIFS(#REF!,#REF!,B24) -> #REF! | H24: =SUMIFS(#REF!,#REF!,B24) -> #REF! | I24: =SUMIFS(#REF!,#REF!,B24) -> #REF! | J24: =SUMIFS('AGT TB Apr -25'!M:M,'AGT TB Apr -25'!S:S,BS!B24)*$J$2 -> 0 | Q24: =SUMIFS(#REF!,#REF!,BS!B24)*$Q$2 -> #REF! | X24: =C24+J24+Q24 -> #REF! | Y24: =D24+K24+R24 -> #REF! | Z24: =E24+L24+S24 -> #REF! | AA24: =F24+M24+T24 -> #REF! | AB24: =G24+N24+U24 -> #REF! | AC24: =H24+O24+V24 -> #REF! | AD24: =I24+P24+W24 -> #REF! | AF24: =X24-AE24 -> #REF!
B25: Advance to Vendor | C25: =SUMIFS(#REF!,#REF!,B25) -> #REF! | D25: =SUMIFS(#REF!,#REF!,B25) -> #REF! | E25: =SUMIFS(#REF!,#REF!,B25) -> #REF! | F25: =SUMIFS(#REF!,#REF!,B25) -> #REF! | G25: =SUMIFS(#REF!,#REF!,B25) -> #REF! | H25: =SUMIFS(#REF!,#REF!,B25) -> #REF! | I25: =SUMIFS(#REF!,#REF!,B25) -> #REF! | J25: =SUMIFS('AGT TB Apr -25'!M:M,'AGT TB Apr -25'!S:S,BS!B25)*$J$2 -> 0 | Q25: =SUMIFS(#REF!,#REF!,BS!B25)*$Q$2 -> #REF! | X25: =C25+J25+Q25 -> #REF! | Y25: =D25+K25+R25 -> #REF! | Z25: =E25+L25+S25 -> #REF! | AA25: =F25+M25+T25 -> #REF! | AB25: =G25+N25+U25 -> #REF! | AC25: =H25+O25+V25 -> #REF! | AD25: =I25+P25+W25 -> #REF! | AF25: =X25-AE25 -> #REF!
B26: LOAN TO SUBSIDIARIES | C26: =SUMIFS(#REF!,#REF!,B26) -> #REF! | D26: =SUMIFS(#REF!,#REF!,B26) -> #REF! | E26: =SUMIFS(#REF!,#REF!,B26) -> #REF! | F26: =SUMIFS(#REF!,#REF!,B26) -> #REF! | G26: =SUMIFS(#REF!,#REF!,B26) -> #REF! | H26: =SUMIFS(#REF!,#REF!,B26) -> #REF! | I26: =SUMIFS(#REF!,#REF!,B26) -> #REF! | J26: =SUMIFS('AGT TB Apr -25'!M:M,'AGT TB Apr -25'!S:S,BS!B26)*$J$2 -> 0 | Q26: =SUMIFS(#REF!,#REF!,BS!B26)*$Q$2 -> #REF! | X26: =C26+J26+Q26 -> #REF! | Y26: =D26+K26+R26 -> #REF! | Z26: =E26+L26+S26 -> #REF! | AA26: =F26+M26+T26 -> #REF! | AB26: =G26+N26+U26 -> #REF! | AC26: =H26+O26+V26 -> #REF! | AD26: =I26+P26+W26 -> #REF! | AE26: =AE51 -> #REF! | AF26: =X26-AE26 -> #REF!
B27: Other Current Asset | C27: =SUMIFS(#REF!,#REF!,B27) -> #REF! | D27: =SUMIFS(#REF!,#REF!,B27) -> #REF! | E27: =SUMIFS(#REF!,#REF!,B27) -> #REF! | F27: =SUMIFS(#REF!,#REF!,B27) -> #REF! | G27: =SUMIFS(#REF!,#REF!,B27) -> #REF! | H27: =SUMIFS(#REF!,#REF!,B27) -> #REF! | I27: =SUMIFS(#REF!,#REF!,B27) -> #REF! | J27: =SUMIFS('AGT TB Apr -25'!M:M,'AGT TB Apr -25'!S:S,BS!B27)*$J$2 -> 0 | Q27: =SUMIFS(#REF!,#REF!,BS!B27)*$Q$2 -> #REF! | X27: =C27+J27+Q27 -> #REF! | Y27: =D27+K27+R27 -> #REF! | Z27: =E27+L27+S27 -> #REF! | AA27: =F27+M27+T27 -> #REF! | AB27: =G27+N27+U27 -> #REF! | AC27: =H27+O27+V27 -> #REF! | AD27: =I27+P27+W27 -> #REF! | AF27: =X27-AE27 -> #REF!
B28: Other Miscelenious Assets | C28: =SUMIFS(#REF!,#REF!,B28) -> #REF! | D28: =SUMIFS(#REF!,#REF!,B28) -> #REF! | E28: =SUMIFS(#REF!,#REF!,B28) -> #REF! | F28: =SUMIFS(#REF!,#REF!,B28) -> #REF! | G28: =SUMIFS(#REF!,#REF!,B28) -> #REF! | H28: =SUMIFS(#REF!,#REF!,B28) -> #REF! | I28: =SUMIFS(#REF!,#REF!,B28) -> #REF! | J28: =SUMIFS('AGT TB Apr -25'!M:M,'AGT TB Apr -25'!S:S,BS!B28)*$J$2 -> 0 | Q28: =SUMIFS(#REF!,#REF!,BS!B28)*$Q$2 -> #REF! | X28: =C28+J28+Q28 -> #REF! | Y28: =D28+K28+R28 -> #REF! | Z28: =E28+L28+S28 -> #REF! | AA28: =F28+M28+T28 -> #REF! | AB28: =G28+N28+U28 -> #REF! | AC28: =H28+O28+V28 -> #REF! | AD28: =I28+P28+W28 -> #REF! | AF28: =X28-AE28 -> #REF!
B29: Employee Advance | C29: =SUMIFS(#REF!,#REF!,B29) -> #REF! | D29: =SUMIFS(#REF!,#REF!,B29) -> #REF! | E29: =SUMIFS(#REF!,#REF!,B29) -> #REF! | F29: =SUMIFS(#REF!,#REF!,B29) -> #REF! | G29: =SUMIFS(#REF!,#REF!,B29) -> #REF! | H29: =SUMIFS(#REF!,#REF!,B29) -> #REF! | I29: =SUMIFS(#REF!,#REF!,B29) -> #REF! | J29: =SUMIFS('AGT TB Apr -25'!M:M,'AGT TB Apr -25'!S:S,BS!B29)*$J$2 -> 0 | Q29: =SUMIFS(#REF!,#REF!,BS!B29)*$Q$2 -> #REF! | X29: =C29+J29+Q29 -> #REF! | Y29: =D29+K29+R29 -> #REF! | Z29: =E29+L29+S29 -> #REF! | AA29: =F29+M29+T29 -> #REF! | AB29: =G29+N29+U29 -> #REF! | AC29: =H29+O29+V29 -> #REF! | AD29: =I29+P29+W29 -> #REF! | AF29: =X29-AE29 -> #REF!
B30: Foreign Exchange | C30: =SUMIFS(#REF!,#REF!,B30) -> #REF! | D30: =SUMIFS(#REF!,#REF!,B30) -> #REF! | E30: =SUMIFS(#REF!,#REF!,B30) -> #REF! | F30: =SUMIFS(#REF!,#REF!,B30) -> #REF! | G30: =SUMIFS(#REF!,#REF!,B30) -> #REF! | H30: =SUMIFS(#REF!,#REF!,B30) -> #REF! | I30: =SUMIFS(#REF!,#REF!,B30) -> #REF! | J30: =SUMIFS('AGT TB Apr -25'!M:M,'AGT TB Apr -25'!S:S,BS!B30)*$J$2 -> 0 | Q30: =SUMIFS(#REF!,#REF!,BS!B30)*$Q$2 -> #REF! | X30: =C30+J30+Q30 -> #REF! | Y30: =D30+K30+R30 -> #REF! | Z30: =E30+L30+S30 -> #REF! | AA30: =F30+M30+T30 -> #REF! | AB30: =G30+N30+U30 -> #REF! | AC30: =H30+O30+V30 -> #REF! | AD30: =I30+P30+W30 -> #REF! | AF30: =X30-AE30 -> #REF!
B31: Duty Drawback Receivable | C31: =SUMIFS(#REF!,#REF!,B31) -> #REF! | D31: =SUMIFS(#REF!,#REF!,B31) -> #REF! | E31: =SUMIFS(#REF!,#REF!,B31) -> #REF! | F31: =SUMIFS(#REF!,#REF!,B31) -> #REF! | G31: =SUMIFS(#REF!,#REF!,B31) -> #REF! | H31: =SUMIFS(#REF!,#REF!,B31) -> #REF! | I31: =SUMIFS(#REF!,#REF!,B31) -> #REF! | J31: =SUMIFS('AGT TB Apr -25'!M:M,'AGT TB Apr -25'!S:S,BS!B31)*$J$2 -> 0 | Q31: =SUMIFS(#REF!,#REF!,BS!B31)*$Q$2 -> #REF! | X31: =C31+J31+Q31 -> #REF! | Y31: =D31+K31+R31 -> #REF! | Z31: =E31+L31+S31 -> #REF! | AA31: =F31+M31+T31 -> #REF! | AB31: =G31+N31+U31 -> #REF! | AC31: =H31+O31+V31 -> #REF! | AD31: =I31+P31+W31 -> #REF! | AF31: =X31-AE31 -> #REF!
B32: ECL GST | C32: =SUMIFS(#REF!,#REF!,B32) -> #REF! | D32: =SUMIFS(#REF!,#REF!,B32) -> #REF! | E32: =SUMIFS(#REF!,#REF!,B32) -> #REF! | F32: =SUMIFS(#REF!,#REF!,B32) -> #REF! | G32: =SUMIFS(#REF!,#REF!,B32) -> #REF! | H32: =SUMIFS(#REF!,#REF!,B32) -> #REF! | I32: =SUMIFS(#REF!,#REF!,B32) -> #REF! | J32: =SUMIFS('AGT TB Apr -25'!M:M,'AGT TB Apr -25'!S:S,BS!B32)*$J$2 -> 0 | Q32: =SUMIFS(#REF!,#REF!,BS!B32)*$Q$2 -> #REF! | X32: =C32+J32+Q32 -> #REF! | Y32: =D32+K32+R32 -> #REF! | Z32: =E32+L32+S32 -> #REF! | AA32: =F32+M32+T32 -> #REF! | AB32: =G32+N32+U32 -> #REF! | AC32: =H32+O32+V32 -> #REF! | AD32: =I32+P32+W32 -> #REF! | AF32: =X32-AE32 -> #REF!
X33: =C33+J33+Q33 -> 0 | Y33: =D33+K33+R33 -> 0 | Z33: =E33+L33+S33 -> 0 | AA33: =F33+M33+T33 -> 0 | AB33: =G33+N33+U33 -> 0 | AC33: =H33+O33+V33 -> 0 | AD33: =I33+P33+W33 -> 0 | AF33: =X33-AE33 -> 0
X34: =C34+J34+Q34 -> 0 | Y34: =D34+K34+R34 -> 0 | Z34: =E34+L34+S34 -> 0 | AA34: =F34+M34+T34 -> 0 | AB34: =G34+N34+U34 -> 0 | AC34: =H34+O34+V34 -> 0 | AD34: =I34+P34+W34 -> 0 | AF34: =X34-AE34 -> 0
B35: Total Assets | C35: =C5+C6+C7+C12+C13+C14+C15+C16 -> #REF! | D35: =D5+D6+D7+D12+D13+D14+D15+D16 -> #REF! | E35: =E5+E6+E7+E12+E13+E14+E15+E16 -> #REF! | F35: =F5+F6+F7+F12+F13+F14+F15+F16 -> #REF! | G35: =G5+G6+G7+G12+G13+G14+G15+G16 -> #REF! | H35: =H5+H6+H7+H12+H13+H14+H15+H16 -> #REF! | I35: =I5+I6+I7+I12+I13+I14+I15+I16 -> #REF! | J35: =J5+J6+J7+J12+J13+J14+J15+J16 -> 0 | Q35: =Q5+Q6+Q7+Q12+Q13+Q14+Q15+Q16 -> #REF! | X35: =X5+X6+X7+X12+X13+X14+X15+X16 -> #REF! | Y35: =Y5+Y6+Y7+Y12+Y13+Y14+Y15+Y16 -> #REF! | Z35: =Z5+Z6+Z7+Z12+Z13+Z14+Z15+Z16 -> #REF! | AA35: =AA5+AA6+AA7+AA12+AA13+AA14+AA15+AA16 -> #REF! | AB35: =AB5+AB6+AB7+AB12+AB13+AB14+AB15+AB16 -> #REF! | AC35: =AC5+AC6+AC7+AC12+AC13+AC14+AC15+AC16 -> #REF! | AD35: =AD5+AD6+AD7+AD12+AD13+AD14+AD15+AD16 -> #REF! | AE35: =SUM(AE5:AE33) -> #REF! | AF35: =AF5+AF6+AF7+AF12+AF13+AF14+AF15+AF16 -> #REF!
X36: =C36+J36+Q36 -> 0 | Y36: =D36+K36+R36 -> 0 | Z36: =E36+L36+S36 -> 0 | AA36: =F36+M36+T36 -> 0 | AB36: =G36+N36+U36 -> 0 | AC36: =H36+O36+V36 -> 0 | AD36: =I36+P36+W36 -> 0 | AF36: =X36-AE36 -> 0
B37: Provision Payable | C37: =SUM(C38:C41) -> #REF! | D37: =SUM(D38:D41) -> #REF! | E37: =SUM(E38:E41) -> #REF! | F37: =SUM(F38:F41) -> #REF! | G37: =SUM(G38:G41) -> #REF! | H37: =SUM(H38:H41) -> #REF! | I37: =SUM(I38:I41) -> #REF! | J37: =SUM(J38:J41) -> 0 | Q37: =SUM(Q38:Q41) -> #REF! | X37: =SUM(X38:X41) -> #REF! | Y37: =SUM(Y38:Y41) -> #REF! | Z37: =SUM(Z38:Z41) -> #REF! | AA37: =SUM(AA38:AA41) -> #REF! | AB37: =SUM(AB38:AB41) -> #REF! | AC37: =SUM(AC38:AC41) -> #REF! | AD37: =SUM(AD38:AD41) -> #REF! | AF37: =SUM(AF38:AF41) -> #REF!
B38: Audit Fees Payable | C38: =-SUMIFS(#REF!,#REF!,B38) -> #REF! | D38: =-SUMIFS(#REF!,#REF!,B38) -> #REF! | E38: =-SUMIFS(#REF!,#REF!,B38) -> #REF! | F38: =-SUMIFS(#REF!,#REF!,B38) -> #REF! | G38: =-SUMIFS(#REF!,#REF!,B38) -> #REF! | H38: =-SUMIFS(#REF!,#REF!,B38) -> #REF! | I38: =-SUMIFS(#REF!,#REF!,B38) -> #REF! | J38: =-SUMIFS('AGT TB Apr -25'!M:M,'AGT TB Apr -25'!S:S,BS!B38)*$J$2 -> 0 | Q38: =-SUMIFS(#REF!,#REF!,BS!B38)*$Q$2 -> #REF! | X38: =C38+J38+Q38 -> #REF! | Y38: =D38+K38+R38 -> #REF! | Z38: =E38+L38+S38 -> #REF! | AA38: =F38+M38+T38 -> #REF! | AB38: =G38+N38+U38 -> #REF! | AC38: =H38+O38+V38 -> #REF! | AD38: =I38+P38+W38 -> #REF! | AF38: =X38-AE38 -> #REF!
B39: Provision for doubtful debts | C39: =-SUMIFS(#REF!,#REF!,B39) -> #REF! | D39: =-SUMIFS(#REF!,#REF!,B39) -> #REF! | E39: =-SUMIFS(#REF!,#REF!,B39) -> #REF! | F39: =-SUMIFS(#REF!,#REF!,B39) -> #REF! | G39: =-SUMIFS(#REF!,#REF!,B39) -> #REF! | H39: =-SUMIFS(#REF!,#REF!,B39) -> #REF! | I39: =-SUMIFS(#REF!,#REF!,B39) -> #REF! | J39: =-SUMIFS('AGT TB Apr -25'!M:M,'AGT TB Apr -25'!S:S,BS!B39)*$J$2 -> 0 | Q39: =-SUMIFS(#REF!,#REF!,BS!B39)*$Q$2 -> #REF! | X39: =C39+J39+Q39 -> #REF! | Y39: =D39+K39+R39 -> #REF! | Z39: =E39+L39+S39 -> #REF! | AA39: =F39+M39+T39 -> #REF! | AB39: =G39+N39+U39 -> #REF! | AC39: =H39+O39+V39 -> #REF! | AD39: =I39+P39+W39 -> #REF! | AF39: =X39-AE39 -> #REF!
B40: Gratuity Payable | C40: =-SUMIFS(#REF!,#REF!,B40) -> #REF! | D40: =-SUMIFS(#REF!,#REF!,B40) -> #REF! | E40: =-SUMIFS(#REF!,#REF!,B40) -> #REF! | F40: =-SUMIFS(#REF!,#REF!,B40) -> #REF! | G40: =-SUMIFS(#REF!,#REF!,B40) -> #REF! | H40: =-SUMIFS(#REF!,#REF!,B40) -> #REF! | I40: =-SUMIFS(#REF!,#REF!,B40) -> #REF! | J40: =-SUMIFS('AGT TB Apr -25'!M:M,'AGT TB Apr -25'!S:S,BS!B40)*$J$2 -> 0 | Q40: =-SUMIFS(#REF!,#REF!,BS!B40)*$Q$2 -> #REF! | X40: =C40+J40+Q40 -> #REF! | Y40: =D40+K40+R40 -> #REF! | Z40: =E40+L40+S40 -> #REF! | AA40: =F40+M40+T40 -> #REF! | AB40: =G40+N40+U40 -> #REF! | AC40: =H40+O40+V40 -> #REF! | AD40: =I40+P40+W40 -> #REF! | AF40: =X40-AE40 -> #REF!
...

Sheet Category Master
A1: Ledger Name | B1: Entity Name | C1: Concate | D1: Group/Legder | E1: PL/BS | F1: Category | G1: Sub Category
A2: Assets | B2: Expora | C2: =_xlfn.CONCAT(Table4[[#This Row],[Ledger Name]],Table4[[#This Row],[Entity Name]]) -> AssetsExpora | D2: Group | E2: 0 | F2: 0 | G2: 0
A3: Account | B3: Expora | C3: =_xlfn.CONCAT(Table4[[#This Row],[Ledger Name]],Table4[[#This Row],[Entity Name]]) -> AccountExpora | D3: Group | E3: 0 | F3: 0 | G3: 0
A4: Accounts Receivable | B4: Expora | C4: =_xlfn.CONCAT(Table4[[#This Row],[Ledger Name]],Table4[[#This Row],[Entity Name]]) -> Accounts ReceivableExpora | D4: Ledger | E4: BS | F4: Trade Receivables | G4: Trade Receivables
A5: Advance TDS (FY21-22) | B5: Expora | C5: =_xlfn.CONCAT(Table4[[#This Row],[Ledger Name]],Table4[[#This Row],[Entity Name]]) -> Advance TDS (FY21-22)Expora | D5: Ledger | E5: BS | F5: Other Current Asset | G5: TDS Receivable
A6: Advance to Vendor | B6: Expora | C6: =_xlfn.CONCAT(Table4[[#This Row],[Ledger Name]],Table4[[#This Row],[Entity Name]]) -> Advance to VendorExpora | D6: Ledger | E6: BS | F6: Other Current Asset | G6: Advance to Vendor
A7: ASPIRARCH MARKET PLATFORMS PRIVATE LIMITED - AXIS BANK | B7: Expora | C7: =_xlfn.CONCAT(Table4[[#This Row],[Ledger Name]],Table4[[#This Row],[Entity Name]]) -> ASPIRARCH MARKET PLATFORMS PRIVATE LIMITED - AXIS BANKExpora | D7: Ledger | E7: BS | F7: Cash and bank balances | G7: Bank Balance
A8: ASPIRARCH MARKET PLATFORMS PVT LTD - CANARA BANK | B8: Expora | C8: =_xlfn.CONCAT(Table4[[#This Row],[Ledger Name]],Table4[[#This Row],[Entity Name]]) -> ASPIRARCH MARKET PLATFORMS PVT LTD - CANARA BANKExpora | D8: Ledger | E8: BS | F8: Cash and bank balances | G8: Bank Balance
A9: ASPIRARCH MARKET PLATFORMS PVT LTD- OD ACCOUNT CANARA | B9: Expora | C9: =_xlfn.CONCAT(Table4[[#This Row],[Ledger Name]],Table4[[#This Row],[Entity Name]]) -> ASPIRARCH MARKET PLATFORMS PVT LTD- OD ACCOUNT CANARAExpora | D9: Ledger | E9: BS | F9: Short-term borrowings | G9: Bank OD
A10: AXIS BANK CC OD | B10: Expora | C10: =_xlfn.CONCAT(Table4[[#This Row],[Ledger Name]],Table4[[#This Row],[Entity Name]]) -> AXIS BANK CC ODExpora | D10: Ledger | E10: BS | F10: Short-term borrowings | G10: Bank OD
A11: Citi Bank | B11: Expora | C11: =_xlfn.CONCAT(Table4[[#This Row],[Ledger Name]],Table4[[#This Row],[Entity Name]]) -> Citi BankExpora | D11: Ledger | E11: BS | F11: Cash and bank balances | G11: Bank Balance
A12: Clearing GL | B12: Expora | C12: =_xlfn.CONCAT(Table4[[#This Row],[Ledger Name]],Table4[[#This Row],[Entity Name]]) -> Clearing GLExpora | D12: Ledger | E12: BS | F12: Other Current Asset | G12: Bank Balance
A13: Computers and Laptops | B13: Expora | C13: =_xlfn.CONCAT(Table4[[#This Row],[Ledger Name]],Table4[[#This Row],[Entity Name]]) -> Computers and LaptopsExpora | D13: Ledger | E13: BS | F13: Fixed assets -Tangible | G13: Fixed assets -Tangible
A14: Apple Mb Air 13.6 M3 8c 8GB 256gb | B14: Expora | C14: =_xlfn.CONCAT(Table4[[#This Row],[Ledger Name]],Table4[[#This Row],[Entity Name]]) -> Apple Mb Air 13.6 M3 8c 8GB 256gbExpora | D14: Ledger | E14: BS | F14: Fixed assets -Tangible | G14: Fixed assets -Tangible
A15: Apple Mb Pro 14 M3 11c 512GB | B15: Expora | C15: =_xlfn.CONCAT(Table4[[#This Row],[Ledger Name]],Table4[[#This Row],[Entity Name]]) -> Apple Mb Pro 14 M3 11c 512GBExpora | D15: Ledger | E15: BS | F15: Fixed assets -Tangible | G15: Fixed assets -Tangible
... A22: Lenovo ThinkPad E14 21E3S06C00 | B22: Expora | C22: =_xlfn.CONCAT(Table4[[#This Row],[Ledger Name]],Table4[[#This Row],[Entity Name]]) -> Lenovo ThinkPad E14 21E3S06C00Expora | D22: Ledger | E22: BS | F22: Fixed assets -Tangible | G22: Fixed assets -Tangible
A23: Total for Computers and Laptops | B23: Expora | C23: =_xlfn.CONCAT(Table4[[#This Row],[Ledger Name]],Table4[[#This Row],[Entity Name]]) -> Total for Computers and LaptopsExpora | D23: Group | E23: 0 | F23: 0 | G23: 0
A24: Duty Drawback Receivable | B24: Expora | C24: =_xlfn.CONCAT(Table4[[#This Row],[Ledger Name]],Table4[[#This Row],[Entity Name]]) -> Duty Drawback ReceivableExpora | D24: Ledger | E24: BS | F24: Other Current Asset | G24: Other Miscelenious Assets
A25: ECGC Premium Advance | B25: Expora | C25: =_xlfn.CONCAT(Table4[[#This Row],[Ledger Name]],Table4[[#This Row],[Entity Name]]) -> ECGC Premium AdvanceExpora | D25: Ledger | E25: BS | F25: Other Current Asset | G25: Other Miscelenious Assets
